Workbook

Sheet Overview
A1: instasure.ca: SEO keyword, page and content plan
A2: Built from the October 2026 competitor research (Ratehub, Rates.ca, PolicyAdvisor, Sun Life, Manulife, Sonnet) and the live site at https://instasure.ca. Generated October 3, 2026.
A4: At a glance
A5: Pages on the site | B5: =COUNTA(Pages!$B$2:$B$829) | C5: All URLs the site serves (Pages tab).
A6: Indexable pages | B6: =COUNTIF(Pages!$I$2:$I$829,"Yes") | C6: In the XML sitemap and open to search engines.
A7: Noindex pages to enrich | B7: =COUNTIF(Pages!$I$2:$I$829,"No") | C7: Thin programmatic pages kept out of search until an editor adds local content.
A8: Keywords in the map | B8: =COUNTA('Nationwide KWs'!$A$2:$A$168)+COUNTA('Provincial KWs'!$A$2:$A$137)+COUNTA('City KWs'!$A$2:$A$419) | C8: Nationwide + Provincial + City tabs.
A9: Nationwide keywords | B9: =COUNTA('Nationwide KWs'!$A$2:$A$168) | C9: Canada-wide head terms and topics.
A10: Provincial keywords | B10: =COUNTA('Provincial KWs'!$A$2:$A$137) | C10: Product + province, regulation and French (Quebec, planned).
A11: City keywords | B11: =COUNTA('City KWs'!$A$2:$A$419) | C11: Product + city, GTA sub-areas and French cities (planned).
A12: Modelled search volume / mo | B12: =SUM('Nationwide KWs'!$D$2:$D$168)+SUM('Provincial KWs'!$E$2:$E$137)+SUM('City KWs'!$F$2:$F$419) | C12: Sum of modelled monthly searches. Use to order work, not to forecast traffic.
A13: Keywords mapped to a live page | B13: =COUNTA('Page-Keyword Map'!$D$2:$D$675) | C13: Rows on the Page-Keyword Map tab.
A14: Keywords in the backlog | B14: =COUNTA('Backlog (Unmapped)'!$A$2:$A$48) | C14: No page yet: planned URLs and blocked items (e.g. French Quebec).
A15: Blog topics planned | B15: =COUNTIF('Blog Content Plan'!$B$2:$B$541,"<>Published") | C15: Blog Content Plan tab (last tab).
A16: Priority 1 topics | B16: =COUNTIFS('Blog Content Plan'!$C$2:$C$541,1,'Blog Content Plan'!$B$2:$B$541,"<>Published") | C16: Write these first.
A17: Blog posts published | B17: =COUNTIF('Blog Content Plan'!$B$2:$B$541,"Published") | C17: The 18 launch guides, plus any you mark Published.
A19: Tabs
A20: Segment Summary | B20: Pages, keywords (by level), volume, backlog and blog topics for each insurance segment.
A21: Pages | B21: Every URL: type, segment, place, indexable, title tag, meta description, H1, primary keyword, keyword counts by level.
A22: Page-Keyword Map | B22: One row per keyword per target page. Primary keyword goes in the title, H1 and first paragraph; secondary keywords in H2s, FAQ and body.
A23: Nationwide KWs | B23: Canada-wide keywords, highest volume first.
A24: Provincial KWs | B24: Province-level keywords, highest volume first.
A25: City KWs | B25: City-level keywords, highest volume first.
A26: Backlog (Unmapped) | B26: Keywords with no page yet, with the planned URL where one is set.
A27: Blog Content Plan | B27: Exhaustive blog topic list per insurance segment from the competitor research: title, URL, focus and secondary keywords, meta title and description, H2 outline, FAQ, value asset, internal links, CTA, schema, competitor gap, optimization and compliance instructions.
A29: How to use
A30: Yellow cells | B30: Fill these in: status, owner, dates, measured volume, current rank. Everything else is data or a formula.
A31: Formulas | B31: Counts, lengths, lookups and "keyword in title?" checks recalculate when you edit the sheet.
A32: Volumes | B32: Modelled estimates (October 2026), not measured. Import Keyword Planner, Ahrefs or Semrush data into the yellow "Measured volume" columns, and into Admin → SEO → Keyword map on the site.
A33: Levels | B33: Nationwide = Canada-wide query. Provincial = names a province or a provincial system (ICBC, FSRA, Care-First). City = names a city or GTA sub-area.
A34: Priority | B34: 1 = do first. Weighs lead value, volume, competitor gap and serviceability. Quebec stays at 3 or lower until AMF registration and French pages exist.
A35: Publishing a blog | B35: Admin → Content on instasure.ca: paste the meta title, meta description and focus keyword from the Blog Content Plan, add the FAQ, sources and a licensed reviewer, then mark the row Published.
A36: Compliance | B36: No "best", "cheapest" or "lowest" claims without a published methodology; estimates are labelled as estimates; verify every fact flagged in the Compliance column against the primary source (see docs/CONTENT_REVIEW.md in the repo).
A37: Source files | B37: Repo NanoQode/Calculators → instasure.ca/docs: STRATEGY.md, SITE_REVIEW.md, KEYWORDS.md, keywords.csv, CONTENT_REVIEW.md, research/*.md.

Sheet Segment Summary
A1: Insurance segment | B1: Pages (all) | C1: Indexable pages | D1: Nationwide keywords | E1: Nationwide volume / mo | F1: Provincial keywords | G1: Provincial volume / mo | H1: City keywords | I1: City volume / mo | J1: Total keyword volume / mo | K1: Unmapped keywords (backlog) | L1: Blog topics planned | M1: Priority 1 topics | N1: Blog posts published
A2: Life insurance | B2: =COUNTIF(Pages!$D$2:$D$829,$A2) | C2: =COUNTIFS(Pages!$D$2:$D$829,$A2,Pages!$I$2:$I$829,"Yes") | D2: =COUNTIF('Nationwide KWs'!$B$2:$B$168,$A2) | E2: =SUMIF('Nationwide KWs'!$B$2:$B$168,$A2,'Nationwide KWs'!$D$2:$D$168) | F2: =COUNTIF('Provincial KWs'!$B$2:$B$137,$A2) | G2: =SUMIF('Provincial KWs'!$B$2:$B$137,$A2,'Provincial KWs'!$E$2:$E$137) | H2: =COUNTIF('City KWs'!$B$2:$B$419,$A2) | I2: =SUMIF('City KWs'!$B$2:$B$419,$A2,'City KWs'!$F$2:$F$419) | J2: =E2+G2+I2 | K2: =COUNTIF('Backlog (Unmapped)'!$C$2:$C$48,$A2) | L2: =COUNTIFS('Blog Content Plan'!$D$2:$D$541,$A2,'Blog Content Plan'!$B$2:$B$541,"<>Published") | M2: =COUNTIFS('Blog Content Plan'!$D$2:$D$541,$A2,'Blog Content Plan'!$C$2:$C$541,1,'Blog Content Plan'!$B$2:$B$541,"<>Published") | N2: =COUNTIFS('Blog Content Plan'!$D$2:$D$541,$A2,'Blog Content Plan'!$B$2:$B$541,"Published")
A3: Mortgage protection | B3: =COUNTIF(Pages!$D$2:$D$829,$A3) | C3: =COUNTIFS(Pages!$D$2:$D$829,$A3,Pages!$I$2:$I$829,"Yes") | D3: =COUNTIF('Nationwide KWs'!$B$2:$B$168,$A3) | E3: =SUMIF('Nationwide KWs'!$B$2:$B$168,$A3,'Nationwide KWs'!$D$2:$D$168) | F3: =COUNTIF('Provincial KWs'!$B$2:$B$137,$A3) | G3: =SUMIF('Provincial KWs'!$B$2:$B$137,$A3,'Provincial KWs'!$E$2:$E$137) | H3: =COUNTIF('City KWs'!$B$2:$B$419,$A3) | I3: =SUMIF('City KWs'!$B$2:$B$419,$A3,'City KWs'!$F$2:$F$419) | J3: =E3+G3+I3 | K3: =COUNTIF('Backlog (Unmapped)'!$C$2:$C$48,$A3) | L3: =COUNTIFS('Blog Content Plan'!$D$2:$D$541,$A3,'Blog Content Plan'!$B$2:$B$541,"<>Published") | M3: =COUNTIFS('Blog Content Plan'!$D$2:$D$541,$A3,'Blog Content Plan'!$C$2:$C$541,1,'Blog Content Plan'!$B$2:$B$541,"<>Published") | N3: =COUNTIFS('Blog Content Plan'!$D$2:$D$541,$A3,'Blog Content Plan'!$B$2:$B$541,"Published")
A4: Critical illness insurance | B4: =COUNTIF(Pages!$D$2:$D$829,$A4) | C4: =COUNTIFS(Pages!$D$2:$D$829,$A4,Pages!$I$2:$I$829,"Yes") | D4: =COUNTIF('Nationwide KWs'!$B$2:$B$168,$A4) | E4: =SUMIF('Nationwide KWs'!$B$2:$B$168,$A4,'Nationwide KWs'!$D$2:$D$168) | F4: =COUNTIF('Provincial KWs'!$B$2:$B$137,$A4) | G4: =SUMIF('Provincial KWs'!$B$2:$B$137,$A4,'Provincial KWs'!$E$2:$E$137) | H4: =COUNTIF('City KWs'!$B$2:$B$419,$A4) | I4: =SUMIF('City KWs'!$B$2:$B$419,$A4,'City KWs'!$F$2:$F$419) | J4: =E4+G4+I4 | K4: =COUNTIF('Backlog (Unmapped)'!$C$2:$C$48,$A4) | L4: =COUNTIFS('Blog Content Plan'!$D$2:$D$541,$A4,'Blog Content Plan'!$B$2:$B$541,"<>Published") | M4: =COUNTIFS('Blog Content Plan'!$D$2:$D$541,$A4,'Blog Content Plan'!$C$2:$C$541,1,'Blog Content Plan'!$B$2:$B$541,"<>Published") | N4: =COUNTIFS('Blog Content Plan'!$D$2:$D$541,$A4,'Blog Content Plan'!$B$2:$B$541,"Published")
A5: Disability insurance | B5: =COUNTIF(Pages!$D$2:$D$829,$A5) | C5: =COUNTIFS(Pages!$D$2:$D$829,$A5,Pages!$I$2:$I$829,"Yes") | D5: =COUNTIF('Nationwide KWs'!$B$2:$B$168,$A5) | E5: =SUMIF('Nationwide KWs'!$B$2:$B$168,$A5,'Nationwide KWs'!$D$2:$D$168) | F5: =COUNTIF('Provincial KWs'!$B$2:$B$137,$A5) | G5: =SUMIF('Provincial KWs'!$B$2:$B$137,$A5,'Provincial KWs'!$E$2:$E$137) | H5: =COUNTIF('City KWs'!$B$2:$B$419,$A5) | I5: =SUMIF('City KWs'!$B$2:$B$419,$A5,'City KWs'!$F$2:$F$419) | J5: =E5+G5+I5 | K5: =COUNTIF('Backlog (Unmapped)'!$C$2:$C$48,$A5) | L5: =COUNTIFS('Blog Content Plan'!$D$2:$D$541,$A5,'Blog Content Plan'!$B$2:$B$541,"<>Published") | M5: =COUNTIFS('Blog Content Plan'!$D$2:$D$541,$A5,'Blog Content Plan'!$C$2:$C$541,1,'Blog Content Plan'!$B$2:$B$541,"<>Published") | N5: =COUNTIFS('Blog Content Plan'!$D$2:$D$541,$A5,'Blog Content Plan'!$B$2:$B$541,"Published")
A6: Health & dental insurance | B6: =COUNTIF(Pages!$D$2:$D$829,$A6) | C6: =COUNTIFS(Pages!$D$2:$D$829,$A6,Pages!$I$2:$I$829,"Yes") | D6: =COUNTIF('Nationwide KWs'!$B$2:$B$168,$A6) | E6: =SUMIF('Nationwide KWs'!$B$2:$B$168,$A6,'Nationwide KWs'!$D$2:$D$168) | F6: =COUNTIF('Provincial KWs'!$B$2:$B$137,$A6) | G6: =SUMIF('Provincial KWs'!$B$2:$B$137,$A6,'Provincial KWs'!$E$2:$E$137) | H6: =COUNTIF('City KWs'!$B$2:$B$419,$A6) | I6: =SUMIF('City KWs'!$B$2:$B$419,$A6,'City KWs'!$F$2:$F$419) | J6: =E6+G6+I6 | K6: =COUNTIF('Backlog (Unmapped)'!$C$2:$C$48,$A6) | L6: =COUNTIFS('Blog Content Plan'!$D$2:$D$541,$A6,'Blog Content Plan'!$B$2:$B$541,"<>Published") | M6: =COUNTIFS('Blog Content Plan'!$D$2:$D$541,$A6,'Blog Content Plan'!$C$2:$C$541,1,'Blog Content Plan'!$B$2:$B$541,"<>Published") | N6: =COUNTIFS('Blog Content Plan'!$D$2:$D$541,$A6,'Blog Content Plan'!$B$2:$B$541,"Published")
A7: Group benefits | B7: =COUNTIF(Pages!$D$2:$D$829,$A7) | C7: =COUNTIFS(Pages!$D$2:$D$829,$A7,Pages!$I$2:$I$829,"Yes") | D7: =COUNTIF('Nationwide KWs'!$B$2:$B$168,$A7) | E7: =SUMIF('Nationwide KWs'!$B$2:$B$168,$A7,'Nationwide KWs'!$D$2:$D$168) | F7: =COUNTIF('Provincial KWs'!$B$2:$B$137,$A7) | G7: =SUMIF('Provincial KWs'!$B$2:$B$137,$A7,'Provincial KWs'!$E$2:$E$137) | H7: =COUNTIF('City KWs'!$B$2:$B$419,$A7) | I7: =SUMIF('City KWs'!$B$2:$B$419,$A7,'City KWs'!$F$2:$F$419) | J7: =E7+G7+I7 | K7: =COUNTIF('Backlog (Unmapped)'!$C$2:$C$48,$A7) | L7: =COUNTIFS('Blog Content Plan'!$D$2:$D$541,$A7,'Blog Content Plan'!$B$2:$B$541,"<>Published") | M7: =COUNTIFS('Blog Content Plan'!$D$2:$D$541,$A7,'Blog Content Plan'!$C$2:$C$541,1,'Blog Content Plan'!$B$2:$B$541,"<>Published") | N7: =COUNTIFS('Blog Content Plan'!$D$2:$D$541,$A7,'Blog Content Plan'!$B$2:$B$541,"Published")
A8: Travel insurance | B8: =COUNTIF(Pages!$D$2:$D$829,$A8) | C8: =COUNTIFS(Pages!$D$2:$D$829,$A8,Pages!$I$2:$I$829,"Yes") | D8: =COUNTIF('Nationwide KWs'!$B$2:$B$168,$A8) | E8: =SUMIF('Nationwide KWs'!$B$2:$B$168,$A8,'Nationwide KWs'!$D$2:$D$168) | F8: =COUNTIF('Provincial KWs'!$B$2:$B$137,$A8) | G8: =SUMIF('Provincial KWs'!$B$2:$B$137,$A8,'Provincial KWs'!$E$2:$E$137) | H8: =COUNTIF('City KWs'!$B$2:$B$419,$A8) | I8: =SUMIF('City KWs'!$B$2:$B$419,$A8,'City KWs'!$F$2:$F$419) | J8: =E8+G8+I8 | K8: =COUNTIF('Backlog (Unmapped)'!$C$2:$C$48,$A8) | L8: =COUNTIFS('Blog Content Plan'!$D$2:$D$541,$A8,'Blog Content Plan'!$B$2:$B$541,"<>Published") | M8: =COUNTIFS('Blog Content Plan'!$D$2:$D$541,$A8,'Blog Content Plan'!$C$2:$C$541,1,'Blog Content Plan'!$B$2:$B$541,"<>Published") | N8: =COUNTIFS('Blog Content Plan'!$D$2:$D$541,$A8,'Blog Content Plan'!$B$2:$B$541,"Published")
A9: Super Visa & visitors insurance | B9: =COUNTIF(Pages!$D$2:$D$829,$A9) | C9: =COUNTIFS(Pages!$D$2:$D$829,$A9,Pages!$I$2:$I$829,"Yes") | D9: =COUNTIF('Nationwide KWs'!$B$2:$B$168,$A9) | E9: =SUMIF('Nationwide KWs'!$B$2:$B$168,$A9,'Nationwide KWs'!$D$2:$D$168) | F9: =COUNTIF('Provincial KWs'!$B$2:$B$137,$A9) | G9: =SUMIF('Provincial KWs'!$B$2:$B$137,$A9,'Provincial KWs'!$E$2:$E$137) | H9: =COUNTIF('City KWs'!$B$2:$B$419,$A9) | I9: =SUMIF('City KWs'!$B$2:$B$419,$A9,'City KWs'!$F$2:$F$419) | J9: =E9+G9+I9 | K9: =COUNTIF('Backlog (Unmapped)'!$C$2:$C$48,$A9) | L9: =COUNTIFS('Blog Content Plan'!$D$2:$D$541,$A9,'Blog Content Plan'!$B$2:$B$541,"<>Published") | M9: =COUNTIFS('Blog Content Plan'!$D$2:$D$541,$A9,'Blog Content Plan'!$C$2:$C$541,1,'Blog Content Plan'!$B$2:$B$541,"<>Published") | N9: =COUNTIFS('Blog Content Plan'!$D$2:$D$541,$A9,'Blog Content Plan'!$B$2:$B$541,"Published")
A10: Car insurance | B10: =COUNTIF(Pages!$D$2:$D$829,$A10) | C10: =COUNTIFS(Pages!$D$2:$D$829,$A10,Pages!$I$2:$I$829,"Yes") | D10: =COUNTIF('Nationwide KWs'!$B$2:$B$168,$A10) | E10: =SUMIF('Nationwide KWs'!$B$2:$B$168,$A10,'Nationwide KWs'!$D$2:$D$168) | F10: =COUNTIF('Provincial KWs'!$B$2:$B$137,$A10) | G10: =SUMIF('Provincial KWs'!$B$2:$B$137,$A10,'Provincial KWs'!$E$2:$E$137) | H10: =COUNTIF('City KWs'!$B$2:$B$419,$A10) | I10: =SUMIF('City KWs'!$B$2:$B$419,$A10,'City KWs'!$F$2:$F$419) | J10: =E10+G10+I10 | K10: =COUNTIF('Backlog (Unmapped)'!$C$2:$C$48,$A10) | L10: =COUNTIFS('Blog Content Plan'!$D$2:$D$541,$A10,'Blog Content Plan'!$B$2:$B$541,"<>Published") | M10: =COUNTIFS('Blog Content Plan'!$D$2:$D$541,$A10,'Blog Content Plan'!$C$2:$C$541,1,'Blog Content Plan'!$B$2:$B$541,"<>Published") | N10: =COUNTIFS('Blog Content Plan'!$D$2:$D$541,$A10,'Blog Content Plan'!$B$2:$B$541,"Published")
A11: Recreational vehicles | B11: =COUNTIF(Pages!$D$2:$D$829,$A11) | C11: =COUNTIFS(Pages!$D$2:$D$829,$A11,Pages!$I$2:$I$829,"Yes") | D11: =COUNTIF('Nationwide KWs'!$B$2:$B$168,$A11) | E11: =SUMIF('Nationwide KWs'!$B$2:$B$168,$A11,'Nationwide KWs'!$D$2:$D$168) | F11: =COUNTIF('Provincial KWs'!$B$2:$B$137,$A11) | G11: =SUMIF('Provincial KWs'!$B$2:$B$137,$A11,'Provincial KWs'!$E$2:$E$137) | H11: =COUNTIF('City KWs'!$B$2:$B$419,$A11) | I11: =SUMIF('City KWs'!$B$2:$B$419,$A11,'City KWs'!$F$2:$F$419) | J11: =E11+G11+I11 | K11: =COUNTIF('Backlog (Unmapped)'!$C$2:$C$48,$A11) | L11: =COUNTIFS('Blog Content Plan'!$D$2:$D$541,$A11,'Blog Content Plan'!$B$2:$B$541,"<>Published") | M11: =COUNTIFS('Blog Content Plan'!$D$2:$D$541,$A11,'Blog Content Plan'!$C$2:$C$541,1,'Blog Content Plan'!$B$2:$B$541,"<>Published") | N11: =COUNTIFS('Blog Content Plan'!$D$2:$D$541,$A11,'Blog Content Plan'!$B$2:$B$541,"Published")
A12: Home insurance | B12: =COUNTIF(Pages!$D$2:$D$829,$A12) | C12: =COUNTIFS(Pages!$D$2:$D$829,$A12,Pages!$I$2:$I$829,"Yes") | D12: =COUNTIF('Nationwide KWs'!$B$2:$B$168,$A12) | E12: =SUMIF('Nationwide KWs'!$B$2:$B$168,$A12,'Nationwide KWs'!$D$2:$D$168) | F12: =COUNTIF('Provincial KWs'!$B$2:$B$137,$A12) | G12: =SUMIF('Provincial KWs'!$B$2:$B$137,$A12,'Provincial KWs'!$E$2:$E$137) | H12: =COUNTIF('City KWs'!$B$2:$B$419,$A12) | I12: =SUMIF('City KWs'!$B$2:$B$419,$A12,'City KWs'!$F$2:$F$419) | J12: =E12+G12+I12 | K12: =COUNTIF('Backlog (Unmapped)'!$C$2:$C$48,$A12) | L12: =COUNTIFS('Blog Content Plan'!$D$2:$D$541,$A12,'Blog Content Plan'!$B$2:$B$541,"<>Published") | M12: =COUNTIFS('Blog Content Plan'!$D$2:$D$541,$A12,'Blog Content Plan'!$C$2:$C$541,1,'Blog Content Plan'!$B$2:$B$541,"<>Published") | N12: =COUNTIFS('Blog Content Plan'!$D$2:$D$541,$A12,'Blog Content Plan'!$B$2:$B$541,"Published")
A13: Condo insurance | B13: =COUNTIF(Pages!$D$2:$D$829,$A13) | C13: =COUNTIFS(Pages!$D$2:$D$829,$A13,Pages!$I$2:$I$829,"Yes") | D13: =COUNTIF('Nationwide KWs'!$B$2:$B$168,$A13) | E13: =SUMIF('Nationwide KWs'!$B$2:$B$168,$A13,'Nationwide KWs'!$D$2:$D$168) | F13: =COUNTIF('Provincial KWs'!$B$2:$B$137,$A13) | G13: =SUMIF('Provincial KWs'!$B$2:$B$137,$A13,'Provincial KWs'!$E$2:$E$137) | H13: =COUNTIF('City KWs'!$B$2:$B$419,$A13) | I13: =SUMIF('City KWs'!$B$2:$B$419,$A13,'City KWs'!$F$2:$F$419) | J13: =E13+G13+I13 | K13: =COUNTIF('Backlog (Unmapped)'!$C$2:$C$48,$A13) | L13: =COUNTIFS('Blog Content Plan'!$D$2:$D$541,$A13,'Blog Content Plan'!$B$2:$B$541,"<>Published") | M13: =COUNTIFS('Blog Content Plan'!$D$2:$D$541,$A13,'Blog Content Plan'!$C$2:$C$541,1,'Blog Content Plan'!$B$2:$B$541,"<>Published") | N13: =COUNTIFS('Blog Content Plan'!$D$2:$D$541,$A13,'Blog Content Plan'!$B$2:$B$541,"Published")
... A23: Site, tools & trust | B23: =COUNTIF(Pages!$D$2:$D$829,$A23) | C23: =COUNTIFS(Pages!$D$2:$D$829,$A23,Pages!$I$2:$I$829,"Yes") | D23: =COUNTIF('Nationwide KWs'!$B$2:$B$168,$A23) | E23: =SUMIF('Nationwide KWs'!$B$2:$B$168,$A23,'Nationwide KWs'!$D$2:$D$168) | F23: =COUNTIF('Provincial KWs'!$B$2:$B$137,$A23) | G23: =SUMIF('Provincial KWs'!$B$2:$B$137,$A23,'Provincial KWs'!$E$2:$E$137) | H23: =COUNTIF('City KWs'!$B$2:$B$419,$A23) | I23: =SUMIF('City KWs'!$B$2:$B$419,$A23,'City KWs'!$F$2:$F$419) | J23: =E23+G23+I23 | K23: =COUNTIF('Backlog (Unmapped)'!$C$2:$C$48,$A23) | L23: =COUNTIFS('Blog Content Plan'!$D$2:$D$541,$A23,'Blog Content Plan'!$B$2:$B$541,"<>Published") | M23: =COUNTIFS('Blog Content Plan'!$D$2:$D$541,$A23,'Blog Content Plan'!$C$2:$C$541,1,'Blog Content Plan'!$B$2:$B$541,"<>Published") | N23: =COUNTIFS('Blog Content Plan'!$D$2:$D$541,$A23,'Blog Content Plan'!$B$2:$B$541,"Published")
A24: Total | B24: =SUM(B2:B23) | C24: =SUM(C2:C23) | D24: =SUM(D2:D23) | E24: =SUM(E2:E23) | F24: =SUM(F2:F23) | G24: =SUM(G2:G23) | H24: =SUM(H2:H23) | I24: =SUM(I2:I23) | ... N24: =SUM(N2:N23)
A26: Every number on this tab is a formula over the other tabs. Volumes are modelled monthly Google searches in Canada (October 2026), not measured data.

Sheet Pages
A1: Page ID | B1: URL | C1: Page type | D1: Insurance segment | E1: Product line | F1: Service | G1: Province | H1: City | I1: Indexable | J1: Title tag | K1: Title length | L1: Meta description | M1: Description length | N1: H1 | O1: Primary keyword | P1: Primary keyword volume | Q1: Primary keyword level | R1: Suggested keyword (not yet in keyword map) | S1: Keywords mapped | T1: Mapped volume / mo | U1: Nationwide keywords | V1: Provincial keywords | W1: City keywords | X1: Primary keyword in title? | Y1: Sitemap priority | Z1: Sitemap file | AA1: Status | AB1: Owner | AC1: Notes
A2: P0001 | B2: https://instasure.ca/ | C2: Static / tool | D2: Site, tools & trust | I2: Yes | J2: Instasure.ca — Compare Insurance Quotes in Canada | Instant Estimates | K2: =LEN(J2) | L2: Instant insurance estimates for life, critical illness, home, tenant, car, travel and business coverage in every province — then a licensed advisor compares… | M2: =LEN(L2) | N2: Compare Canadian insurance quotes. Instant estimates in 60 seconds. | S2: =COUNTIF('Page-Keyword Map'!$A$2:$A$675,B2) | T2: =SUMIF('Page-Keyword Map'!$A$2:$A$675,B2,'Page-Keyword Map'!$H$2:$H$675) | U2: =COUNTIFS('Page-Keyword Map'!$A$2:$A$675,B2,'Page-Keyword Map'!$E$2:$E$675,"Nationwide") | V2: =COUNTIFS('Page-Keyword Map'!$A$2:$A$675,B2,'Page-Keyword Map'!$E$2:$E$675,"Provincial") | W2: =COUNTIFS('Page-Keyword Map'!$A$2:$A$675,B2,'Page-Keyword Map'!$E$2:$E$675,"City") | X2: =IF(O2="","",IF(ISNUMBER(SEARCH(O2,J2)),"Yes","No")) | Y2: 1 | Z2: sitemap-core.xml | AA2: Live – indexable
A3: P0002 | B3: https://instasure.ca/about/ | C3: Static / tool | D3: Site, tools & trust | I3: Yes | J3: About Instasure.ca | K3: =LEN(J3) | L3: Instasure.ca helps Canadians understand insurance and price it instantly, then connects them with advisors licensed in their province. | M3: =LEN(L3) | N3: About Instasure.ca | S3: =COUNTIF('Page-Keyword Map'!$A$2:$A$675,B3) | T3: =SUMIF('Page-Keyword Map'!$A$2:$A$675,B3,'Page-Keyword Map'!$H$2:$H$675) | U3: =COUNTIFS('Page-Keyword Map'!$A$2:$A$675,B3,'Page-Keyword Map'!$E$2:$E$675,"Nationwide") | V3: =COUNTIFS('Page-Keyword Map'!$A$2:$A$675,B3,'Page-Keyword Map'!$E$2:$E$675,"Provincial") | W3: =COUNTIFS('Page-Keyword Map'!$A$2:$A$675,B3,'Page-Keyword Map'!$E$2:$E$675,"City") | X3: =IF(O3="","",IF(ISNUMBER(SEARCH(O3,J3)),"Yes","No")) | Y3: 0.4 | Z3: sitemap-core.xml | AA3: Live – indexable
A4: P0003 | B4: https://instasure.ca/accessibility/ | C4: Static / tool | D4: Site, tools & trust | I4: Yes | J4: Accessibility | Instasure.ca | K4: =LEN(J4) | L4: Instasure.ca’s commitment to an accessible website for all Canadians, including AODA and WCAG 2.1 AA alignment. | M4: =LEN(L4) | N4: Accessibility | S4: =COUNTIF('Page-Keyword Map'!$A$2:$A$675,B4) | T4: =SUMIF('Page-Keyword Map'!$A$2:$A$675,B4,'Page-Keyword Map'!$H$2:$H$675) | U4: =COUNTIFS('Page-Keyword Map'!$A$2:$A$675,B4,'Page-Keyword Map'!$E$2:$E$675,"Nationwide") | V4: =COUNTIFS('Page-Keyword Map'!$A$2:$A$675,B4,'Page-Keyword Map'!$E$2:$E$675,"Provincial") | W4: =COUNTIFS('Page-Keyword Map'!$A$2:$A$675,B4,'Page-Keyword Map'!$E$2:$E$675,"City") | X4: =IF(O4="","",IF(ISNUMBER(SEARCH(O4,J4)),"Yes","No")) | Y4: 0.2 | Z4: sitemap-core.xml | AA4: Live – indexable
A5: P0004 | B5: https://instasure.ca/advisors/ | C5: Static / tool | D5: Site, tools & trust | I5: Yes | J5: Licensed Insurance Advisors Across Canada | Instasure.ca | K5: =LEN(J5) | L5: Meet Instasure’s licensed insurance advisors. Every advisor is licensed in the provinces they serve and matched to you by province, product and language. | M5: =LEN(L5) | N5: Licensed insurance advisors across Canada | O5: insurance broker near me | P5: 6600 | Q5: Nationwide | S5: =COUNTIF('Page-Keyword Map'!$A$2:$A$675,B5) | T5: =SUMIF('Page-Keyword Map'!$A$2:$A$675,B5,'Page-Keyword Map'!$H$2:$H$675) | U5: =COUNTIFS('Page-Keyword Map'!$A$2:$A$675,B5,'Page-Keyword Map'!$E$2:$E$675,"Nationwide") | V5: =COUNTIFS('Page-Keyword Map'!$A$2:$A$675,B5,'Page-Keyword Map'!$E$2:$E$675,"Provincial") | W5: =COUNTIFS('Page-Keyword Map'!$A$2:$A$675,B5,'Page-Keyword Map'!$E$2:$E$675,"City") | X5: =IF(O5="","",IF(ISNUMBER(SEARCH(O5,J5)),"Yes","No")) | Y5: 0.7 | Z5: sitemap-core.xml | AA5: Live – indexable
A6: P0005 | B6: https://instasure.ca/calculators/ | C6: Static / tool | D6: Site, tools & trust | I6: Yes | J6: Free Insurance Calculators for Canadians | Instasure.ca | K6: =LEN(J6) | L6: Free Canadian insurance calculators: life insurance needs, mortgage protection vs term life, tenant & condo coverage and small-business coverage — instant results,… | M6: =LEN(L6) | N6: Insurance calculators for Canadians | S6: =COUNTIF('Page-Keyword Map'!$A$2:$A$675,B6) | T6: =SUMIF('Page-Keyword Map'!$A$2:$A$675,B6,'Page-Keyword Map'!$H$2:$H$675) | U6: =COUNTIFS('Page-Keyword Map'!$A$2:$A$675,B6,'Page-Keyword Map'!$E$2:$E$675,"Nationwide") | V6: =COUNTIFS('Page-Keyword Map'!$A$2:$A$675,B6,'Page-Keyword Map'!$E$2:$E$675,"Provincial") | W6: =COUNTIFS('Page-Keyword Map'!$A$2:$A$675,B6,'Page-Keyword Map'!$E$2:$E$675,"City") | X6: =IF(O6="","",IF(ISNUMBER(SEARCH(O6,J6)),"Yes","No")) | Y6: 0.8 | Z6: sitemap-core.xml | AA6: Live – indexable
A7: P0006 | B7: https://instasure.ca/calculators/business-coverage/ | C7: Static / tool | D7: Site, tools & trust | I7: Yes | J7: Small Business Insurance Coverage Checker | Instasure.ca | K7: =LEN(J7) | L7: Answer a few questions about your business to see recommended CGL, E&O, property and cyber coverage plus an instant cost estimate. | M7: =LEN(L7) | N7: What business insurance do I need? | O7: business insurance calculator | P7: 140 | Q7: Nationwide | S7: =COUNTIF('Page-Keyword Map'!$A$2:$A$675,B7) | T7: =SUMIF('Page-Keyword Map'!$A$2:$A$675,B7,'Page-Keyword Map'!$H$2:$H$675) | U7: =COUNTIFS('Page-Keyword Map'!$A$2:$A$675,B7,'Page-Keyword Map'!$E$2:$E$675,"Nationwide") | V7: =COUNTIFS('Page-Keyword Map'!$A$2:$A$675,B7,'Page-Keyword Map'!$E$2:$E$675,"Provincial") | W7: =COUNTIFS('Page-Keyword Map'!$A$2:$A$675,B7,'Page-Keyword Map'!$E$2:$E$675,"City") | X7: =IF(O7="","",IF(ISNUMBER(SEARCH(O7,J7)),"Yes","No")) | Y7: 0.6 | Z7: sitemap-core.xml | AA7: Live – indexable
A8: P0007 | B8: https://instasure.ca/calculators/life-insurance-needs/ | C8: Static / tool | D8: Site, tools & trust | I8: Yes | J8: Life Insurance Needs Calculator (Canada) | Instasure.ca | K8: =LEN(J8) | L8: Calculate how much life insurance your family needs using your income, mortgage, debts, childcare and education costs — built for Canadian households. | M8: =LEN(L8) | N8: How much life insurance do I need? | O8: life insurance calculator | P8: 2400 | Q8: Nationwide | S8: =COUNTIF('Page-Keyword Map'!$A$2:$A$675,B8) | T8: =SUMIF('Page-Keyword Map'!$A$2:$A$675,B8,'Page-Keyword Map'!$H$2:$H$675) | U8: =COUNTIFS('Page-Keyword Map'!$A$2:$A$675,B8,'Page-Keyword Map'!$E$2:$E$675,"Nationwide") | V8: =COUNTIFS('Page-Keyword Map'!$A$2:$A$675,B8,'Page-Keyword Map'!$E$2:$E$675,"Provincial") | W8: =COUNTIFS('Page-Keyword Map'!$A$2:$A$675,B8,'Page-Keyword Map'!$E$2:$E$675,"City") | X8: =IF(O8="","",IF(ISNUMBER(SEARCH(O8,J8)),"Yes","No")) | Y8: 0.8 | Z8: sitemap-core.xml | AA8: Live – indexable
A9: P0008 | B9: https://instasure.ca/calculators/mortgage-protection/ | C9: Static / tool | D9: Site, tools & trust | I9: Yes | J9: Mortgage Life Insurance vs Term Life Calculator | Instasure.ca | K9: =LEN(J9) | L9: Compare the cost and payout of bank mortgage creditor insurance against a personal term life policy for your mortgage balance and age. | M9: =LEN(L9) | N9: Mortgage protection calculator: bank insurance vs term life | O9: mortgage life insurance calculator | P9: 260 | Q9: Nationwide | S9: =COUNTIF('Page-Keyword Map'!$A$2:$A$675,B9) | T9: =SUMIF('Page-Keyword Map'!$A$2:$A$675,B9,'Page-Keyword Map'!$H$2:$H$675) | U9: =COUNTIFS('Page-Keyword Map'!$A$2:$A$675,B9,'Page-Keyword Map'!$E$2:$E$675,"Nationwide") | V9: =COUNTIFS('Page-Keyword Map'!$A$2:$A$675,B9,'Page-Keyword Map'!$E$2:$E$675,"Provincial") | W9: =COUNTIFS('Page-Keyword Map'!$A$2:$A$675,B9,'Page-Keyword Map'!$E$2:$E$675,"City") | X9: =IF(O9="","",IF(ISNUMBER(SEARCH(O9,J9)),"Yes","No")) | Y9: 0.6 | Z9: sitemap-core.xml | AA9: Live – indexable
A10: P0009 | B10: https://instasure.ca/calculators/tenant-condo-coverage/ | C10: Static / tool | D10: Site, tools & trust | I10: Yes | J10: Tenant & Condo Insurance Coverage Calculator | Instasure.ca | K10: =LEN(J10) | L10: Estimate the replacement value of your belongings, condo improvements and the deductible-assessment coverage your building requires. | M10: =LEN(L10) | N10: How much tenant or condo insurance do I need? | O10: how much contents insurance do i need | P10: 260 | Q10: Nationwide | S10: =COUNTIF('Page-Keyword Map'!$A$2:$A$675,B10) | T10: =SUMIF('Page-Keyword Map'!$A$2:$A$675,B10,'Page-Keyword Map'!$H$2:$H$675) | U10: =COUNTIFS('Page-Keyword Map'!$A$2:$A$675,B10,'Page-Keyword Map'!$E$2:$E$675,"Nationwide") | V10: =COUNTIFS('Page-Keyword Map'!$A$2:$A$675,B10,'Page-Keyword Map'!$E$2:$E$675,"Provincial") | W10: =COUNTIFS('Page-Keyword Map'!$A$2:$A$675,B10,'Page-Keyword Map'!$E$2:$E$675,"City") | X10: =IF(O10="","",IF(ISNUMBER(SEARCH(O10,J10)),"Yes","No")) | Y10: 0.6 | Z10: sitemap-core.xml | AA10: Live – indexable
A11: P0010 | B11: https://instasure.ca/compare/ | C11: Static / tool | D11: Site, tools & trust | I11: Yes | J11: Compare life insurance options in Canada (2026) | Instasure.ca | K11: =LEN(J11) | L11: Side-by-side comparison of life insurance options in Canada — price, underwriting speed, medical requirements and features — with instant estimates and licensed… | M11: =LEN(L11) | N11: Compare life insurance options | O11: compare insurance quotes canada | P11: 1000 | Q11: Nationwide | S11: =COUNTIF('Page-Keyword Map'!$A$2:$A$675,B11) | T11: =SUMIF('Page-Keyword Map'!$A$2:$A$675,B11,'Page-Keyword Map'!$H$2:$H$675) | U11: =COUNTIFS('Page-Keyword Map'!$A$2:$A$675,B11,'Page-Keyword Map'!$E$2:$E$675,"Nationwide") | V11: =COUNTIFS('Page-Keyword Map'!$A$2:$A$675,B11,'Page-Keyword Map'!$E$2:$E$675,"Provincial") | W11: =COUNTIFS('Page-Keyword Map'!$A$2:$A$675,B11,'Page-Keyword Map'!$E$2:$E$675,"City") | X11: =IF(O11="","",IF(ISNUMBER(SEARCH(O11,J11)),"Yes","No")) | Y11: 0.7 | Z11: sitemap-core.xml | AA11: Live – indexable
A12: P0011 | B12: https://instasure.ca/contact/ | C12: Static / tool | D12: Site, tools & trust | I12: Yes | J12: Contact Instasure — Book a Free Licensed Advisor Review | K12: =LEN(J12) | L12: Book a free, no-obligation insurance review with an advisor licensed in your province, or send us a question. | M12: =LEN(L12) | N12: Talk to a licensed advisor | S12: =COUNTIF('Page-Keyword Map'!$A$2:$A$675,B12) | T12: =SUMIF('Page-Keyword Map'!$A$2:$A$675,B12,'Page-Keyword Map'!$H$2:$H$675) | U12: =COUNTIFS('Page-Keyword Map'!$A$2:$A$675,B12,'Page-Keyword Map'!$E$2:$E$675,"Nationwide") | V12: =COUNTIFS('Page-Keyword Map'!$A$2:$A$675,B12,'Page-Keyword Map'!$E$2:$E$675,"Provincial") | W12: =COUNTIFS('Page-Keyword Map'!$A$2:$A$675,B12,'Page-Keyword Map'!$E$2:$E$675,"City") | X12: =IF(O12="","",IF(ISNUMBER(SEARCH(O12,J12)),"Yes","No")) | Y12: 0.4 | Z12: sitemap-core.xml | AA12: Live – indexable
A13: P0012 | B13: https://instasure.ca/editorial-guidelines/ | C13: Static / tool | D13: Site, tools & trust | I13: Yes | J13: Editorial guidelines | Instasure.ca | K13: =LEN(J13) | L13: How Instasure.ca researches, writes, reviews and updates its insurance guides — sources, expert review, corrections and independence. | M13: =LEN(L13) | N13: Editorial guidelines | S13: =COUNTIF('Page-Keyword Map'!$A$2:$A$675,B13) | T13: =SUMIF('Page-Keyword Map'!$A$2:$A$675,B13,'Page-Keyword Map'!$H$2:$H$675) | U13: =COUNTIFS('Page-Keyword Map'!$A$2:$A$675,B13,'Page-Keyword Map'!$E$2:$E$675,"Nationwide") | V13: =COUNTIFS('Page-Keyword Map'!$A$2:$A$675,B13,'Page-Keyword Map'!$E$2:$E$675,"Provincial") | W13: =COUNTIFS('Page-Keyword Map'!$A$2:$A$675,B13,'Page-Keyword Map'!$E$2:$E$675,"City") | X13: =IF(O13="","",IF(ISNUMBER(SEARCH(O13,J13)),"Yes","No")) | Y13: 0.4 | Z13: sitemap-core.xml | AA13: Live – indexable
A14: P0013 | B14: https://instasure.ca/glossary/ | C14: Static / tool | D14: Site, tools & trust | I14: Yes | J14: Canadian Insurance Glossary: Plain-Language Definitions | K14: =LEN(J14) | L14: Plain-language definitions of Canadian insurance terms — from accident benefits and DCPD to riders, simplified issue and deductible assessments. | M14: =LEN(L14) | N14: Canadian insurance glossary | O14: car insurance deductible | P14: 880 | Q14: Nationwide | S14: =COUNTIF('Page-Keyword Map'!$A$2:$A$675,B14) | T14: =SUMIF('Page-Keyword Map'!$A$2:$A$675,B14,'Page-Keyword Map'!$H$2:$H$675) | U14: =COUNTIFS('Page-Keyword Map'!$A$2:$A$675,B14,'Page-Keyword Map'!$E$2:$E$675,"Nationwide") | V14: =COUNTIFS('Page-Keyword Map'!$A$2:$A$675,B14,'Page-Keyword Map'!$E$2:$E$675,"Provincial") | W14: =COUNTIFS('Page-Keyword Map'!$A$2:$A$675,B14,'Page-Keyword Map'!$E$2:$E$675,"City") | X14: =IF(O14="","",IF(ISNUMBER(SEARCH(O14,J14)),"Yes","No")) | Y14: 0.5 | Z14: sitemap-core.xml | AA14: Live – indexable
A15: P0014 | B15: https://instasure.ca/guides/ | C15: Static / tool | D15: Site, tools & trust | I15: Yes | J15: Insurance Guides for Canadians — Knowledge & Risk Center | K15: =LEN(J15) | L15: Plain-language Canadian insurance guides: life, critical illness, home, tenant, car, travel and business coverage — with calculators, province rules and… | M15: =LEN(L15) | N15: Insurance Knowledge & Risk Center | S15: =COUNTIF('Page-Keyword Map'!$A$2:$A$675,B15) | T15: =SUMIF('Page-Keyword Map'!$A$2:$A$675,B15,'Page-Keyword Map'!$H$2:$H$675) | U15: =COUNTIFS('Page-Keyword Map'!$A$2:$A$675,B15,'Page-Keyword Map'!$E$2:$E$675,"Nationwide") | V15: =COUNTIFS('Page-Keyword Map'!$A$2:$A$675,B15,'Page-Keyword Map'!$E$2:$E$675,"Provincial") | W15: =COUNTIFS('Page-Keyword Map'!$A$2:$A$675,B15,'Page-Keyword Map'!$E$2:$E$675,"City") | X15: =IF(O15="","",IF(ISNUMBER(SEARCH(O15,J15)),"Yes","No")) | Y15: 0.8 | Z15: sitemap-core.xml | AA15: Live – indexable
A16: P0015 | B16: https://instasure.ca/how-we-make-money/ | C16: Static / tool | D16: Site, tools & trust | I16: Yes | J16: How Instasure makes money | Instasure.ca | K16: =LEN(J16) | L16: Transparency about how Instasure.ca is paid, how advisors are compensated, and how that affects (and doesn’t affect) what you pay. | M16: =LEN(L16) | N16: How Instasure makes money | S16: =COUNTIF('Page-Keyword Map'!$A$2:$A$675,B16) | T16: =SUMIF('Page-Keyword Map'!$A$2:$A$675,B16,'Page-Keyword Map'!$H$2:$H$675) | U16: =COUNTIFS('Page-Keyword Map'!$A$2:$A$675,B16,'Page-Keyword Map'!$E$2:$E$675,"Nationwide") | V16: =COUNTIFS('Page-Keyword Map'!$A$2:$A$675,B16,'Page-Keyword Map'!$E$2:$E$675,"Provincial") | W16: =COUNTIFS('Page-Keyword Map'!$A$2:$A$675,B16,'Page-Keyword Map'!$E$2:$E$675,"City") | X16: =IF(O16="","",IF(ISNUMBER(SEARCH(O16,J16)),"Yes","No")) | Y16: 0.4 | Z16: sitemap-core.xml | AA16: Live – indexable
A17: P0016 | B17: https://instasure.ca/insights/rate-index/ | C17: Static / tool | D17: Site, tools & trust | I17: No | J17: Instasure Rate Index — Canadian Insurance Estimates (October 2026) | K17: =LEN(J17) | L17: Quarterly index of Canadian insurance estimate ranges by product and province, built from anonymised Instasure quote requests. | M17: =LEN(L17) | N17: Instasure Rate Index | O17: average car insurance cost canada | P17: 2900 | Q17: Nationwide | S17: =COUNTIF('Page-Keyword Map'!$A$2:$A$675,B17) | T17: =SUMIF('Page-Keyword Map'!$A$2:$A$675,B17,'Page-Keyword Map'!$H$2:$H$675) | U17: =COUNTIFS('Page-Keyword Map'!$A$2:$A$675,B17,'Page-Keyword Map'!$E$2:$E$675,"Nationwide") | V17: =COUNTIFS('Page-Keyword Map'!$A$2:$A$675,B17,'Page-Keyword Map'!$E$2:$E$675,"Provincial") | W17: =COUNTIFS('Page-Keyword Map'!$A$2:$A$675,B17,'Page-Keyword Map'!$E$2:$E$675,"City") | X17: =IF(O17="","",IF(ISNUMBER(SEARCH(O17,J17)),"Yes","No")) | Y17: 0.7 | Z17: (not listed: noindex) | AA17: Live – noindex (enrich before indexing)
A18: P0017 | B18: https://instasure.ca/insurance-services/ | C18: Static / tool | D18: Cross-product & brand | I18: Yes | J18: All Insurance Services & Specialist Desks in Canada | K18: =LEN(J18) | L18: Every type of insurance Instasure covers, from car, home and life to pet, boat, landlord and commercial auto, plus specialist desks for hard-to-place needs. | M18: =LEN(L18) | N18: Every kind of insurance, one licensed advisor | O18: types of insurance in canada | P18: 1000 | Q18: Nationwide | S18: =COUNTIF('Page-Keyword Map'!$A$2:$A$675,B18) | T18: =SUMIF('Page-Keyword Map'!$A$2:$A$675,B18,'Page-Keyword Map'!$H$2:$H$675) | U18: =COUNTIFS('Page-Keyword Map'!$A$2:$A$675,B18,'Page-Keyword Map'!$E$2:$E$675,"Nationwide") | V18: =COUNTIFS('Page-Keyword Map'!$A$2:$A$675,B18,'Page-Keyword Map'!$E$2:$E$675,"Provincial") | W18: =COUNTIFS('Page-Keyword Map'!$A$2:$A$675,B18,'Page-Keyword Map'!$E$2:$E$675,"City") | X18: =IF(O18="","",IF(ISNUMBER(SEARCH(O18,J18)),"Yes","No")) | Y18: 0.8 | Z18: sitemap-core.xml | AA18: Live – indexable
A19: P0018 | B19: https://instasure.ca/insurance/ | C19: Static / tool | D19: Multi-line (place hubs) | I19: Yes | J19: Insurance in Canada by Province & Territory | Instasure.ca | K19: =LEN(J19) | L19: How insurance works in each Canadian province and territory — regulators, public vs private auto insurance, local risks and licensed advisors. | M19: =LEN(L19) | N19: Insurance in Canada, province by province | S19: =COUNTIF('Page-Keyword Map'!$A$2:$A$675,B19) | T19: =SUMIF('Page-Keyword Map'!$A$2:$A$675,B19,'Page-Keyword Map'!$H$2:$H$675) | U19: =COUNTIFS('Page-Keyword Map'!$A$2:$A$675,B19,'Page-Keyword Map'!$E$2:$E$675,"Nationwide") | V19: =COUNTIFS('Page-Keyword Map'!$A$2:$A$675,B19,'Page-Keyword Map'!$E$2:$E$675,"Provincial") | W19: =COUNTIFS('Page-Keyword Map'!$A$2:$A$675,B19,'Page-Keyword Map'!$E$2:$E$675,"City") | X19: =IF(O19="","",IF(ISNUMBER(SEARCH(O19,J19)),"Yes","No")) | Y19: 0.7 | Z19: sitemap-core.xml | AA19: Live – indexable
A20: P0019 | B20: https://instasure.ca/licensing/ | C20: Static / tool | D20: Site, tools & trust | I20: Yes | J20: Licensing & disclosures | Instasure.ca | K20: =LEN(J20) | L20: Licensing, regulatory and complaint information for Instasure.ca and the licensed advisors who serve its users. | M20: =LEN(L20) | N20: Licensing & disclosures | S20: =COUNTIF('Page-Keyword Map'!$A$2:$A$675,B20) | T20: =SUMIF('Page-Keyword Map'!$A$2:$A$675,B20,'Page-Keyword Map'!$H$2:$H$675) | U20: =COUNTIFS('Page-Keyword Map'!$A$2:$A$675,B20,'Page-Keyword Map'!$E$2:$E$675,"Nationwide") | V20: =COUNTIFS('Page-Keyword Map'!$A$2:$A$675,B20,'Page-Keyword Map'!$E$2:$E$675,"Provincial") | W20: =COUNTIFS('Page-Keyword Map'!$A$2:$A$675,B20,'Page-Keyword Map'!$E$2:$E$675,"City") | X20: =IF(O20="","",IF(ISNUMBER(SEARCH(O20,J20)),"Yes","No")) | Y20: 0.4 | Z20: sitemap-core.xml | AA20: Live – indexable
A21: P0020 | B21: https://instasure.ca/privacy/ | C21: Static / tool | D21: Site, tools & trust | I21: Yes | J21: Privacy policy | Instasure.ca | K21: =LEN(J21) | L21: How Instasure.ca collects, uses, shares and protects personal information under PIPEDA and applicable provincial privacy laws, including Quebec’s Law 25. | M21: =LEN(L21) | N21: Privacy policy | S21: =COUNTIF('Page-Keyword Map'!$A$2:$A$675,B21) | T21: =SUMIF('Page-Keyword Map'!$A$2:$A$675,B21,'Page-Keyword Map'!$H$2:$H$675) | U21: =COUNTIFS('Page-Keyword Map'!$A$2:$A$675,B21,'Page-Keyword Map'!$E$2:$E$675,"Nationwide") | V21: =COUNTIFS('Page-Keyword Map'!$A$2:$A$675,B21,'Page-Keyword Map'!$E$2:$E$675,"Provincial") | W21: =COUNTIFS('Page-Keyword Map'!$A$2:$A$675,B21,'Page-Keyword Map'!$E$2:$E$675,"City") | X21: =IF(O21="","",IF(ISNUMBER(SEARCH(O21,J21)),"Yes","No")) | Y21: 0.2 | Z21: sitemap-core.xml | AA21: Live – indexable
A22: P0021 | B22: https://instasure.ca/quote/ | C22: Static / tool | D22: Site, tools & trust | I22: Yes | J22: Get an Instant Insurance Quote in Canada | Instasure.ca | K22: =LEN(J22) | L22: Choose your coverage and get an instant premium estimate in about 60 seconds — life, critical illness, disability, home, tenant, condo, car, travel, Super Visa and… | M22: =LEN(L22) | N22: What would you like to insure? | O22: insurance quotes | P22: 6600 | Q22: Nationwide | S22: =COUNTIF('Page-Keyword Map'!$A$2:$A$675,B22) | T22: =SUMIF('Page-Keyword Map'!$A$2:$A$675,B22,'Page-Keyword Map'!$H$2:$H$675) | U22: =COUNTIFS('Page-Keyword Map'!$A$2:$A$675,B22,'Page-Keyword Map'!$E$2:$E$675,"Nationwide") | V22: =COUNTIFS('Page-Keyword Map'!$A$2:$A$675,B22,'Page-Keyword Map'!$E$2:$E$675,"Provincial") | W22: =COUNTIFS('Page-Keyword Map'!$A$2:$A$675,B22,'Page-Keyword Map'!$E$2:$E$675,"City") | X22: =IF(O22="","",IF(ISNUMBER(SEARCH(O22,J22)),"Yes","No")) | Y22: 0.9 | Z22: sitemap-core.xml | AA22: Live – indexable
A23: P0022 | B23: https://instasure.ca/site-map/ | C23: Static / tool | D23: Site, tools & trust | I23: Yes | J23: Site map | Instasure.ca | K23: =LEN(J23) | L23: Every guide, product, province and city page on Instasure.ca. | M23: =LEN(L23) | N23: Site map | S23: =COUNTIF('Page-Keyword Map'!$A$2:$A$675,B23) | T23: =SUMIF('Page-Keyword Map'!$A$2:$A$675,B23,'Page-Keyword Map'!$H$2:$H$675) | U23: =COUNTIFS('Page-Keyword Map'!$A$2:$A$675,B23,'Page-Keyword Map'!$E$2:$E$675,"Nationwide") | V23: =COUNTIFS('Page-Keyword Map'!$A$2:$A$675,B23,'Page-Keyword Map'!$E$2:$E$675,"Provincial") | W23: =COUNTIFS('Page-Keyword Map'!$A$2:$A$675,B23,'Page-Keyword Map'!$E$2:$E$675,"City") | X23: =IF(O23="","",IF(ISNUMBER(SEARCH(O23,J23)),"Yes","No")) | Y23: 0.3 | Z23: sitemap-core.xml | AA23: Live – indexable
A24: P0023 | B24: https://instasure.ca/terms/ | C24: Static / tool | D24: Site, tools & trust | I24: Yes | J24: Terms of use | Instasure.ca | K24: =LEN(J24) | L24: Terms governing your use of Instasure.ca, its guides, calculators and instant estimates. | M24: =LEN(L24) | N24: Terms of use | S24: =COUNTIF('Page-Keyword Map'!$A$2:$A$675,B24) | T24: =SUMIF('Page-Keyword Map'!$A$2:$A$675,B24,'Page-Keyword Map'!$H$2:$H$675) | U24: =COUNTIFS('Page-Keyword Map'!$A$2:$A$675,B24,'Page-Keyword Map'!$E$2:$E$675,"Nationwide") | V24: =COUNTIFS('Page-Keyword Map'!$A$2:$A$675,B24,'Page-Keyword Map'!$E$2:$E$675,"Provincial") | W24: =COUNTIFS('Page-Keyword Map'!$A$2:$A$675,B24,'Page-Keyword Map'!$E$2:$E$675,"City") | X24: =IF(O24="","",IF(ISNUMBER(SEARCH(O24,J24)),"Yes","No")) | Y24: 0.2 | Z24: sitemap-core.xml | AA24: Live – indexable
A25: P0024 | B25: https://instasure.ca/business-insurance/ | C25: Product pillar | D25: Business insurance | E25: Business Insurance | I25: Yes | J25: Small Business Insurance (2026) | Instasure.ca | K25: =LEN(J25) | L25: From sole proprietors to growing teams — the coverage clients, landlords and contracts require. Instant business insurance estimates for every province,… | M25: =LEN(L25) | N25: Small Business Insurance: Liability, Property & Professional Coverage | O25: business insurance | P25: 8100 | Q25: Nationwide | S25: =COUNTIF('Page-Keyword Map'!$A$2:$A$675,B25) | T25: =SUMIF('Page-Keyword Map'!$A$2:$A$675,B25,'Page-Keyword Map'!$H$2:$H$675) | U25: =COUNTIFS('Page-Keyword Map'!$A$2:$A$675,B25,'Page-Keyword Map'!$E$2:$E$675,"Nationwide") | V25: =COUNTIFS('Page-Keyword Map'!$A$2:$A$675,B25,'Page-Keyword Map'!$E$2:$E$675,"Provincial") | W25: =COUNTIFS('Page-Keyword Map'!$A$2:$A$675,B25,'Page-Keyword Map'!$E$2:$E$675,"City") | X25: =IF(O25="","",IF(ISNUMBER(SEARCH(O25,J25)),"Yes","No")) | Y25: 0.9 | Z25: sitemap-core.xml | AA25: Live – indexable
A26: P0025 | B26: https://instasure.ca/car-insurance/ | C26: Product pillar | D26: Car insurance | E26: Car Insurance | I26: Yes | J26: Car Insurance Quotes (2026) | Instasure.ca | K26: =LEN(J26) | L26: See what drivers like you pay, then let a licensed advisor compare insurers for you. Instant car insurance estimates for every province, plain-language guidance… | M26: =LEN(L26) | N26: Car Insurance Quotes: Compare Rates in Minutes | O26: car insurance | P26: 74000 | Q26: Nationwide | S26: =COUNTIF('Page-Keyword Map'!$A$2:$A$675,B26) | T26: =SUMIF('Page-Keyword Map'!$A$2:$A$675,B26,'Page-Keyword Map'!$H$2:$H$675) | U26: =COUNTIFS('Page-Keyword Map'!$A$2:$A$675,B26,'Page-Keyword Map'!$E$2:$E$675,"Nationwide") | V26: =COUNTIFS('Page-Keyword Map'!$A$2:$A$675,B26,'Page-Keyword Map'!$E$2:$E$675,"Provincial") | W26: =COUNTIFS('Page-Keyword Map'!$A$2:$A$675,B26,'Page-Keyword Map'!$E$2:$E$675,"City") | X26: =IF(O26="","",IF(ISNUMBER(SEARCH(O26,J26)),"Yes","No")) | Y26: 0.9 | Z26: sitemap-core.xml | AA26: Live – indexable
A27: P0026 | B27: https://instasure.ca/condo-insurance/ | C27: Product pillar | D27: Condo insurance | E27: Condo Insurance | I27: Yes | J27: Condo Insurance (2026) | Instasure.ca | K27: =LEN(J27) | L27: Your corporation’s policy covers the building — not your belongings, upgrades or your share of a large deductible. Instant condo insurance estimates for every… | M27: =LEN(L27) | N27: Condo Insurance: Unit, Improvements & Deductible Assessment Coverage | O27: condo insurance | P27: 6600 | Q27: Nationwide | S27: =COUNTIF('Page-Keyword Map'!$A$2:$A$675,B27) | T27: =SUMIF('Page-Keyword Map'!$A$2:$A$675,B27,'Page-Keyword Map'!$H$2:$H$675) | U27: =COUNTIFS('Page-Keyword Map'!$A$2:$A$675,B27,'Page-Keyword Map'!$E$2:$E$675,"Nationwide") | V27: =COUNTIFS('Page-Keyword Map'!$A$2:$A$675,B27,'Page-Keyword Map'!$E$2:$E$675,"Provincial") | W27: =COUNTIFS('Page-Keyword Map'!$A$2:$A$675,B27,'Page-Keyword Map'!$E$2:$E$675,"City") | X27: =IF(O27="","",IF(ISNUMBER(SEARCH(O27,J27)),"Yes","No")) | Y27: 0.9 | Z27: sitemap-core.xml | AA27: Live – indexable
A28: P0027 | B28: https://instasure.ca/contractor-insurance/ | C28: Product pillar | D28: Contractor & trades insurance | E28: Contractor Insurance | I28: Yes | J28: Contractor Insurance for Trades (2026) | Instasure.ca | K28: =LEN(J28) | L28: Get the certificate the general contractor or homeowner needs — fast. Instant contractor insurance estimates for every province, plain-language guidance and… | M28: =LEN(L28) | N28: Contractor Insurance for Trades: Liability, Tools & Equipment | O28: contractor insurance | P28: 1300 | Q28: Nationwide | S28: =COUNTIF('Page-Keyword Map'!$A$2:$A$675,B28) | T28: =SUMIF('Page-Keyword Map'!$A$2:$A$675,B28,'Page-Keyword Map'!$H$2:$H$675) | U28: =COUNTIFS('Page-Keyword Map'!$A$2:$A$675,B28,'Page-Keyword Map'!$E$2:$E$675,"Nationwide") | V28: =COUNTIFS('Page-Keyword Map'!$A$2:$A$675,B28,'Page-Keyword Map'!$E$2:$E$675,"Provincial") | W28: =COUNTIFS('Page-Keyword Map'!$A$2:$A$675,B28,'Page-Keyword Map'!$E$2:$E$675,"City") | X28: =IF(O28="","",IF(ISNUMBER(SEARCH(O28,J28)),"Yes","No")) | Y28: 0.9 | Z28: sitemap-core.xml | AA28: Live – indexable
A29: P0028 | B29: https://instasure.ca/critical-illness-insurance/ | C29: Product pillar | D29: Critical illness insurance | E29: Critical Illness Insurance | I29: Yes | J29: Critical Illness Insurance in Canada (2026) | Instasure.ca | K29: =LEN(J29) | L29: A lump-sum payment after a covered diagnosis like cancer, heart attack or stroke — spend it however recovery requires. Instant critical illness insurance estimates… | M29: =LEN(L29) | N29: Critical Illness Insurance in Canada: Tax-Free Cash If You Get Sick | O29: critical illness insurance | P29: 6600 | Q29: Nationwide | S29: =COUNTIF('Page-Keyword Map'!$A$2:$A$675,B29) | T29: =SUMIF('Page-Keyword Map'!$A$2:$A$675,B29,'Page-Keyword Map'!$H$2:$H$675) | U29: =COUNTIFS('Page-Keyword Map'!$A$2:$A$675,B29,'Page-Keyword Map'!$E$2:$E$675,"Nationwide") | V29: =COUNTIFS('Page-Keyword Map'!$A$2:$A$675,B29,'Page-Keyword Map'!$E$2:$E$675,"Provincial") | W29: =COUNTIFS('Page-Keyword Map'!$A$2:$A$675,B29,'Page-Keyword Map'!$E$2:$E$675,"City") | X29: =IF(O29="","",IF(ISNUMBER(SEARCH(O29,J29)),"Yes","No")) | Y29: 0.9 | Z29: sitemap-core.xml | AA29: Live – indexable
A30: P0029 | B30: https://instasure.ca/disability-insurance/ | C30: Product pillar | D30: Disability insurance | E30: Disability Insurance | I30: Yes | J30: Disability Insurance in Canada (2026) | Instasure.ca | K30: =LEN(J30) | L30: Monthly income if illness or injury stops you from working — essential for the self-employed. Instant disability insurance estimates for every province,… | M30: =LEN(L30) | N30: Disability Insurance in Canada: Protect Your Income | O30: disability insurance | P30: 4400 | Q30: Nationwide | S30: =COUNTIF('Page-Keyword Map'!$A$2:$A$675,B30) | T30: =SUMIF('Page-Keyword Map'!$A$2:$A$675,B30,'Page-Keyword Map'!$H$2:$H$675) | U30: =COUNTIFS('Page-Keyword Map'!$A$2:$A$675,B30,'Page-Keyword Map'!$E$2:$E$675,"Nationwide") | V30: =COUNTIFS('Page-Keyword Map'!$A$2:$A$675,B30,'Page-Keyword Map'!$E$2:$E$675,"Provincial") | W30: =COUNTIFS('Page-Keyword Map'!$A$2:$A$675,B30,'Page-Keyword Map'!$E$2:$E$675,"City") | X30: =IF(O30="","",IF(ISNUMBER(SEARCH(O30,J30)),"Yes","No")) | Y30: 0.9 | Z30: sitemap-core.xml | AA30: Live – indexable
A31: P0030 | B31: https://instasure.ca/group-benefits/ | C31: Product pillar | D31: Group benefits | E31: Group Benefits | I31: Yes | J31: Group Benefits for Small Businesses (2026) | Instasure.ca | K31: =LEN(J31) | L31: Attract and keep great people with a benefits plan sized for teams of 2 to 200. Instant group benefits estimates for every province, plain-language guidance and… | M31: =LEN(L31) | N31: Group Benefits for Small Businesses: Health, Dental & More | O31: group benefits for small business | P31: 1300 | Q31: Nationwide | S31: =COUNTIF('Page-Keyword Map'!$A$2:$A$675,B31) | T31: =SUMIF('Page-Keyword Map'!$A$2:$A$675,B31,'Page-Keyword Map'!$H$2:$H$675) | U31: =COUNTIFS('Page-Keyword Map'!$A$2:$A$675,B31,'Page-Keyword Map'!$E$2:$E$675,"Nationwide") | V31: =COUNTIFS('Page-Keyword Map'!$A$2:$A$675,B31,'Page-Keyword Map'!$E$2:$E$675,"Provincial") | W31: =COUNTIFS('Page-Keyword Map'!$A$2:$A$675,B31,'Page-Keyword Map'!$E$2:$E$675,"City") | X31: =IF(O31="","",IF(ISNUMBER(SEARCH(O31,J31)),"Yes","No")) | Y31: 0.9 | Z31: sitemap-core.xml | AA31: Live – indexable
A32: P0031 | B32: https://instasure.ca/health-dental-insurance/ | C32: Product pillar | D32: Health & dental insurance | E32: Health & Dental Insurance | I32: Yes | J32: Health & Dental Insurance for Individuals and Families (2026) | K32: =LEN(J32) | L32: Prescription drugs, dental, vision and paramedical care that provincial plans don’t fully cover. Instant health & dental insurance estimates for every province,… | M32: =LEN(L32) | N32: Health & Dental Insurance for Individuals and Families | O32: dental insurance | P32: 8100 | Q32: Nationwide | S32: =COUNTIF('Page-Keyword Map'!$A$2:$A$675,B32) | T32: =SUMIF('Page-Keyword Map'!$A$2:$A$675,B32,'Page-Keyword Map'!$H$2:$H$675) | U32: =COUNTIFS('Page-Keyword Map'!$A$2:$A$675,B32,'Page-Keyword Map'!$E$2:$E$675,"Nationwide") | V32: =COUNTIFS('Page-Keyword Map'!$A$2:$A$675,B32,'Page-Keyword Map'!$E$2:$E$675,"Provincial") | W32: =COUNTIFS('Page-Keyword Map'!$A$2:$A$675,B32,'Page-Keyword Map'!$E$2:$E$675,"City") | X32: =IF(O32="","",IF(ISNUMBER(SEARCH(O32,J32)),"Yes","No")) | Y32: 0.9 | Z32: sitemap-core.xml | AA32: Live – indexable
A33: P0032 | B33: https://instasure.ca/home-insurance/ | C33: Product pillar | D33: Home insurance | E33: Home Insurance | I33: Yes | J33: Home Insurance Quotes (2026) | Instasure.ca | K33: =LEN(J33) | L33: Coverage built for Canadian risks — water, wind, hail, wildfire and theft. Instant home insurance estimates for every province, plain-language guidance and… | M33: =LEN(L33) | N33: Home Insurance Quotes: Protect Your House, Belongings & Liability | O33: home insurance | P33: 27000 | Q33: Nationwide | S33: =COUNTIF('Page-Keyword Map'!$A$2:$A$675,B33) | T33: =SUMIF('Page-Keyword Map'!$A$2:$A$675,B33,'Page-Keyword Map'!$H$2:$H$675) | U33: =COUNTIFS('Page-Keyword Map'!$A$2:$A$675,B33,'Page-Keyword Map'!$E$2:$E$675,"Nationwide") | V33: =COUNTIFS('Page-Keyword Map'!$A$2:$A$675,B33,'Page-Keyword Map'!$E$2:$E$675,"Provincial") | W33: =COUNTIFS('Page-Keyword Map'!$A$2:$A$675,B33,'Page-Keyword Map'!$E$2:$E$675,"City") | X33: =IF(O33="","",IF(ISNUMBER(SEARCH(O33,J33)),"Yes","No")) | Y33: 0.9 | Z33: sitemap-core.xml | AA33: Live – indexable
A34: P0033 | B34: https://instasure.ca/life-insurance/ | C34: Product pillar | D34: Life insurance | E34: Life Insurance | I34: Yes | J34: Life Insurance in Canada (2026) | Instasure.ca | K34: =LEN(J34) | L34: Protect your family’s income, mortgage and future with term or permanent coverage from leading Canadian insurers. Instant life insurance estimates for every… | M34: =LEN(L34) | N34: Life Insurance in Canada: Compare Quotes in 60 Seconds | O34: life insurance | P34: 33000 | Q34: Nationwide | S34: =COUNTIF('Page-Keyword Map'!$A$2:$A$675,B34) | T34: =SUMIF('Page-Keyword Map'!$A$2:$A$675,B34,'Page-Keyword Map'!$H$2:$H$675) | U34: =COUNTIFS('Page-Keyword Map'!$A$2:$A$675,B34,'Page-Keyword Map'!$E$2:$E$675,"Nationwide") | V34: =COUNTIFS('Page-Keyword Map'!$A$2:$A$675,B34,'Page-Keyword Map'!$E$2:$E$675,"Provincial") | W34: =COUNTIFS('Page-Keyword Map'!$A$2:$A$675,B34,'Page-Keyword Map'!$E$2:$E$675,"City") | X34: =IF(O34="","",IF(ISNUMBER(SEARCH(O34,J34)),"Yes","No")) | Y34: 0.9 | Z34: sitemap-core.xml | AA34: Live – indexable
A35: P0034 | B35: https://instasure.ca/mortgage-life-insurance/ | C35: Product pillar | D35: Mortgage protection | E35: Mortgage Life Insurance | I35: Yes | J35: Mortgage Life Insurance vs Term Life (2026) | Instasure.ca | K35: =LEN(J35) | L35: Make sure your family keeps the house — without overpaying for bank creditor insurance. Instant mortgage life insurance estimates for every province,… | M35: =LEN(L35) | N35: Mortgage Life Insurance vs Term Life: Protect Your Home for Less | O35: mortgage life insurance | P35: 2400 | Q35: Nationwide | S35: =COUNTIF('Page-Keyword Map'!$A$2:$A$675,B35) | T35: =SUMIF('Page-Keyword Map'!$A$2:$A$675,B35,'Page-Keyword Map'!$H$2:$H$675) | U35: =COUNTIFS('Page-Keyword Map'!$A$2:$A$675,B35,'Page-Keyword Map'!$E$2:$E$675,"Nationwide") | V35: =COUNTIFS('Page-Keyword Map'!$A$2:$A$675,B35,'Page-Keyword Map'!$E$2:$E$675,"Provincial") | W35: =COUNTIFS('Page-Keyword Map'!$A$2:$A$675,B35,'Page-Keyword Map'!$E$2:$E$675,"City") | X35: =IF(O35="","",IF(ISNUMBER(SEARCH(O35,J35)),"Yes","No")) | Y35: 0.9 | Z35: sitemap-core.xml | AA35: Live – indexable
A36: P0035 | B36: https://instasure.ca/no-medical-life-insurance/ | C36: Product pillar | D36: Life insurance | E36: No-Medical Life Insurance | I36: Yes | J36: No-Medical Life Insurance in Canada (2026) | Instasure.ca | K36: =LEN(J36) | L36: Fast approval with health questions instead of needles — including options if you have a medical condition. Instant no-medical life insurance estimates for every… | M36: =LEN(L36) | N36: No-Medical Life Insurance in Canada: Get Covered Without an Exam | O36: no medical life insurance | P36: 1300 | Q36: Nationwide | S36: =COUNTIF('Page-Keyword Map'!$A$2:$A$675,B36) | T36: =SUMIF('Page-Keyword Map'!$A$2:$A$675,B36,'Page-Keyword Map'!$H$2:$H$675) | U36: =COUNTIFS('Page-Keyword Map'!$A$2:$A$675,B36,'Page-Keyword Map'!$E$2:$E$675,"Nationwide") | V36: =COUNTIFS('Page-Keyword Map'!$A$2:$A$675,B36,'Page-Keyword Map'!$E$2:$E$675,"Provincial") | W36: =COUNTIFS('Page-Keyword Map'!$A$2:$A$675,B36,'Page-Keyword Map'!$E$2:$E$675,"City") | X36: =IF(O36="","",IF(ISNUMBER(SEARCH(O36,J36)),"Yes","No")) | Y36: 0.9 | Z36: sitemap-core.xml | AA36: Live – indexable
... A42: P0041 | B42: https://instasure.ca/whole-life-insurance/ | C42: Product pillar | D42: Life insurance | E42: Whole Life Insurance | I42: Yes | J42: Whole Life Insurance in Canada (2026) | Instasure.ca | K42: =LEN(J42) | L42: Lifetime coverage with guaranteed premiums and cash value — for estate, legacy and business planning. Instant whole life insurance estimates for every province,… | M42: =LEN(L42) | N42: Whole Life Insurance in Canada: Costs, Cash Value & When It Makes Sense | O42: whole life insurance | P42: 5400 | Q42: Nationwide | S42: =COUNTIF('Page-Keyword Map'!$A$2:$A$675,B42) | T42: =SUMIF('Page-Keyword Map'!$A$2:$A$675,B42,'Page-Keyword Map'!$H$2:$H$675) | U42: =COUNTIFS('Page-Keyword Map'!$A$2:$A$675,B42,'Page-Keyword Map'!$E$2:$E$675,"Nationwide") | V42: =COUNTIFS('Page-Keyword Map'!$A$2:$A$675,B42,'Page-Keyword Map'!$E$2:$E$675,"Provincial") | W42: =COUNTIFS('Page-Keyword Map'!$A$2:$A$675,B42,'Page-Keyword Map'!$E$2:$E$675,"City") | X42: =IF(O42="","",IF(ISNUMBER(SEARCH(O42,J42)),"Yes","No")) | Y42: 0.9 | Z42: sitemap-core.xml | AA42: Live – indexable
A43: P0042 | B43: https://instasure.ca/atv-snowmobile-insurance/ | C43: Service page | D43: Recreational vehicles | E43: Car Insurance | F43: ATV & Snowmobile Insurance | I43: Yes | J43: ATV & Snowmobile Insurance in Canada | Instasure.ca | K43: =LEN(J43) | L43: Insurance for ATVs, side-by-sides and snowmobiles: when it is required, trail permits, liability and damage coverage, and seasonal pricing. | M43: =LEN(L43) | N43: ATV & Snowmobile Insurance | O43: snowmobile insurance | P43: 1000 | Q43: Nationwide | S43: =COUNTIF('Page-Keyword Map'!$A$2:$A$675,B43) | T43: =SUMIF('Page-Keyword Map'!$A$2:$A$675,B43,'Page-Keyword Map'!$H$2:$H$675) | U43: =COUNTIFS('Page-Keyword Map'!$A$2:$A$675,B43,'Page-Keyword Map'!$E$2:$E$675,"Nationwide") | V43: =COUNTIFS('Page-Keyword Map'!$A$2:$A$675,B43,'Page-Keyword Map'!$E$2:$E$675,"Provincial") | W43: =COUNTIFS('Page-Keyword Map'!$A$2:$A$675,B43,'Page-Keyword Map'!$E$2:$E$675,"City") | X43: =IF(O43="","",IF(ISNUMBER(SEARCH(O43,J43)),"Yes","No")) | Y43: 0.7 | Z43: sitemap-services.xml | AA43: Live – indexable
A44: P0043 | B44: https://instasure.ca/boat-insurance/ | C44: Service page | D44: Recreational vehicles | E44: Home Insurance | F44: Boat Insurance | I44: Yes | J44: Boat Insurance in Canada: Pleasure Craft and Watercraft | K44: =LEN(J44) | L44: Boat and personal watercraft insurance in Canada: liability, hull and equipment coverage, what a home policy covers and marina requirements. | M44: =LEN(L44) | N44: Boat Insurance | O44: boat insurance | P44: 2900 | Q44: Nationwide | S44: =COUNTIF('Page-Keyword Map'!$A$2:$A$675,B44) | T44: =SUMIF('Page-Keyword Map'!$A$2:$A$675,B44,'Page-Keyword Map'!$H$2:$H$675) | U44: =COUNTIFS('Page-Keyword Map'!$A$2:$A$675,B44,'Page-Keyword Map'!$E$2:$E$675,"Nationwide") | V44: =COUNTIFS('Page-Keyword Map'!$A$2:$A$675,B44,'Page-Keyword Map'!$E$2:$E$675,"Provincial") | W44: =COUNTIFS('Page-Keyword Map'!$A$2:$A$675,B44,'Page-Keyword Map'!$E$2:$E$675,"City") | X44: =IF(O44="","",IF(ISNUMBER(SEARCH(O44,J44)),"Yes","No")) | Y44: 0.7 | Z44: sitemap-services.xml | AA44: Live – indexable
A45: P0044 | B45: https://instasure.ca/business-insurance/commercial-auto/ | C45: Service page | D45: Business insurance | E45: Business Insurance | F45: Commercial Auto & Fleet Insurance | I45: Yes | J45: Commercial Auto Insurance: Vans, Trucks and Small Fleets | K45: =LEN(J45) | L45: Commercial vehicle insurance for Canadian businesses: work vans, pickups, small fleets, trucking and cargo, employee drivers and what personal policies exclude. | M45: =LEN(L45) | N45: Commercial Auto & Fleet Insurance | O45: commercial auto insurance | P45: 1300 | Q45: Nationwide | S45: =COUNTIF('Page-Keyword Map'!$A$2:$A$675,B45) | T45: =SUMIF('Page-Keyword Map'!$A$2:$A$675,B45,'Page-Keyword Map'!$H$2:$H$675) | U45: =COUNTIFS('Page-Keyword Map'!$A$2:$A$675,B45,'Page-Keyword Map'!$E$2:$E$675,"Nationwide") | V45: =COUNTIFS('Page-Keyword Map'!$A$2:$A$675,B45,'Page-Keyword Map'!$E$2:$E$675,"Provincial") | W45: =COUNTIFS('Page-Keyword Map'!$A$2:$A$675,B45,'Page-Keyword Map'!$E$2:$E$675,"City") | X45: =IF(O45="","",IF(ISNUMBER(SEARCH(O45,J45)),"Yes","No")) | Y45: 0.8 | Z45: sitemap-services.xml | AA45: Live – indexable
...

Sheet Page-Keyword Map
A1: URL | B1: Page type | C1: Insurance segment | D1: Keyword | E1: Level | F1: Province | G1: City | H1: Volume / mo (modelled) | I1: Difficulty (0–100) | J1: Intent | K1: Cluster | L1: Priority (1 = first) | M1: Role on page | N1: Keyword in page title? | O1: Competitors seen | P1: Notes
A2: https://instasure.ca/car-insurance/ | B2: Product pillar | C2: Car insurance | D2: car insurance | E2: Nationwide | H2: 74000 | I2: 85 | J2: commercial | K2: auto-core | L2: 2 | M2: Primary | N2: =IFERROR(IF(ISNUMBER(SEARCH(D2,INDEX(Pages!$J$2:$J$829,MATCH(A2,Pages!$B$2:$B$829,0)))),"Yes","No"),"Page not found") | O2: ratehub, rates.ca, kanetix, mychoice, insurer brands | P2: Head term. Win through province and city depth rather than head-on.
A3: https://instasure.ca/car-insurance/ | B3: Product pillar | C3: Car insurance | D3: auto insurance | E3: Nationwide | H3: 33000 | I3: 82 | J3: commercial | K3: auto-core | L3: 3 | M3: Secondary | N3: =IFERROR(IF(ISNUMBER(SEARCH(D3,INDEX(Pages!$J$2:$J$829,MATCH(A3,Pages!$B$2:$B$829,0)))),"Yes","No"),"Page not found") | O3: ratehub, rates.ca, insurer brands | P3: Synonym. Use in H2s and meta descriptions, not a separate page.
A4: https://instasure.ca/car-insurance/ | B4: Product pillar | C4: Car insurance | D4: cheap car insurance | E4: Nationwide | H4: 9900 | I4: 75 | J4: transactional | K4: auto-cost | L4: 2 | M4: Secondary | N4: =IFERROR(IF(ISNUMBER(SEARCH(D4,INDEX(Pages!$J$2:$J$829,MATCH(A4,Pages!$B$2:$B$829,0)))),"Yes","No"),"Page not found") | O4: ratehub (15 ways), rates.ca, mychoice | P4: Answer with savings factors and compare. No "cheapest" claim without a published methodology.
A5: https://instasure.ca/travel-insurance/ | B5: Product pillar | C5: Travel insurance | D5: travel insurance | E5: Nationwide | H5: 40000 | I5: 80 | J5: commercial | K5: travel | L5: 3 | M5: Primary | N5: =IFERROR(IF(ISNUMBER(SEARCH(D5,INDEX(Pages!$J$2:$J$829,MATCH(A5,Pages!$B$2:$B$829,0)))),"Yes","No"),"Page not found") | O5: sun life, manulife, credit cards, ratehub | P5: Huge but low lead value. Capture through super visa, snowbird and visitors.
A6: https://instasure.ca/travel-insurance/ | B6: Product pillar | C6: Travel insurance | D6: out of province travel insurance | E6: Nationwide | H6: 480 | I6: 35 | J6: informational | K6: travel | L6: 3 | M6: Secondary | N6: =IFERROR(IF(ISNUMBER(SEARCH(D6,INDEX(Pages!$J$2:$J$829,MATCH(A6,Pages!$B$2:$B$829,0)))),"Yes","No"),"Page not found") | O6: sun life
A7: https://instasure.ca/home-insurance/ | B7: Product pillar | C7: Home insurance | D7: home insurance | E7: Nationwide | H7: 27000 | I7: 82 | J7: commercial | K7: property-core | L7: 1 | M7: Primary | N7: =IFERROR(IF(ISNUMBER(SEARCH(D7,INDEX(Pages!$J$2:$J$829,MATCH(A7,Pages!$B$2:$B$829,0)))),"Yes","No"),"Page not found") | O7: ratehub, rates.ca, sonnet, insurer brands
A8: https://instasure.ca/home-insurance/ | B8: Product pillar | C8: Home insurance | D8: house insurance | E8: Nationwide | H8: 8100 | I8: 75 | J8: commercial | K8: property-core | L8: 2 | M8: Secondary | N8: =IFERROR(IF(ISNUMBER(SEARCH(D8,INDEX(Pages!$J$2:$J$829,MATCH(A8,Pages!$B$2:$B$829,0)))),"Yes","No"),"Page not found") | O8: ratehub, rates.ca
