Workbook

Sheet Instasure Topic Plan
A1: Product | B1: Mortgage Protection | C1: Term Life Insurance | D1: Life Insurance Basics & Buying | E1: Life Insurance Basics & Buying | F1: Life Insurance Basics & Buying | G1: Permanent & Whole Life | H1: No Medical & Instant Life | I1: Health Insurance | J1: No Medical & Instant Life | K1: Critical Illness | L1: Family Life Insurance | M1: Life Insurance with Medical Conditions | N1: Life Insurance with Medical Conditions | O1: Permanent & Whole Life | P1: Term Life Insurance | Q1: Final Expense | R1: Family Life Insurance | S1: Seniors (50+) | T1: Seniors (50+) | U1: Term Life Insurance | V1: Universal Life | W1: Life Insurance Basics & Buying | X1: Life Insurance Basics & Buying | Y1: Life Insurance Basics & Buying | Z1: Life Insurance with Medical Conditions | AA1: Permanent & Whole Life | AB1: Life Insurance Basics & Buying | AC1: Life Insurance with Medical Conditions | AD1: Permanent & Whole Life | AE1: Seniors (50+) | AF1: Term Life Insurance | AG1: Universal Life | AH1: Final Expense | AI1: Family Life Insurance | AJ1: Joint Life | AK1: Life Insurance with Medical Conditions | AL1: Life Insurance with Medical Conditions | AM1: Life Insurance Basics & Buying | AN1: Life Insurance Basics & Buying | AO1: Life Insurance Basics & Buying | AP1: Critical Illness | AQ1: Family Life Insurance | AR1: Family Life Insurance | AS1: Health Insurance | AT1: Health Insurance | AU1: Joint Life | AV1: Life Insurance with Medical Conditions | AW1: Term Life Insurance | AX1: Life Insurance Basics & Buying | AY1: Final Expense | AZ1: Family Life Insurance | BA1: Joint Life | BB1: Mortgage Protection | BC1: No Medical & Instant Life
A2: Topic (H1) | B2: Mortgage Insurance in Canada: Default Insurance vs Mortgage Life Insurance Explained | C2: What Is Term Life Insurance and How Does It Work in Canada? | D2: How Does Life Insurance Work in Canada? Premiums, Payouts and Policies Explained | E2: Types of Life Insurance in Canada: Term, Whole, Universal and No-Medical Explained | F2: Is Life Insurance Worth It in Canada? When You Need It and When You Don't | G2: How Much Does Whole Life Insurance Cost in Canada? | H2: Instant Life Insurance in Canada: How Online Approval Works and How Products Compare | I2: Health Insurance After Losing Your Job: Conversion Plans and Your Options | J2: Declined for Life Insurance? Why It Happens and What to Do Next in Canada | K2: Is Critical Illness Insurance Worth It in Canada? A Decision Guide | L2: Family Life Insurance in Canada: How to Protect Everyone You Love | M2: Life Insurance With Pre-Existing Conditions in Canada: Your Options | N2: Life Insurance Medical Exams and Applications: What Insurers Ask and How to Prepare | O2: Term 100 Life Insurance in Canada: Lifetime Cover Without the Cash Value | P2: 10, 20 or 30-Year Term Life Insurance: How to Choose the Right Length | Q2: Funeral Insurance for Seniors: What You Can Buy at 60, 70 and 80 | R2: How to Choose a Life Insurance Beneficiary in Canada: Spouses, Children, Estates and Trusts | S2: Life Insurance Over 70 in Canada: Options, Age Limits and Costs | T2: Life Insurance Over 50 in Canada: Costs, Types and How Much You Need | U2: What Happens When Term Life Insurance Expires? Renewal, Conversion and Your Options | V2: Whole Life vs Universal Life Insurance: How They Differ in Canada | W2: How to Make a Life Insurance Claim in Canada: Steps, Documents and Timelines | X2: Life Insurance Riders in Canada: Which Add-Ons Are Worth Paying For? | Y2: What Does Life Insurance Not Cover? Exclusions Every Canadian Should Know | Z2: Life Insurance With Diabetes in Canada: Type 1, Type 2 and What Underwriters Look For | AA2: Participating Whole Life Insurance: Dividends, Cash Value and Surrender Value Explained | AB2: What Affects Life Insurance Rates in Canada? How Quotes Are Calculated | AC2: Life Insurance After Cancer in Canada: Waiting Periods, Remission and Your Options | AD2: Buy Term and Invest the Difference: Does It Work in Canada? | AE2: Using Life Insurance for Estate Planning in Canada: Capital Gains at Death, Cottages and Inheritances | AF2: Decreasing Term vs Level Term Life Insurance for Your Mortgage | AG2: How Does Universal Life Insurance Work in Canada? | AH2: Funeral Insurance With No Medical Exam: How to Qualify and What It Costs | AI2: Life Insurance for New Parents in Canada: How Much, What Type and When to Buy | AJ2: Funding a Buy-Sell Agreement With Life Insurance: A Guide for Canadian Business Owners | AK2: Life Insurance After a Heart Attack or With Heart Disease in Canada | AL2: How Life Insurance Companies Check Your Medical History in Canada | AM2: Life Insurance Broker vs Agent vs Bank vs Online: Where Should You Buy? | AN2: How to Choose a Life Insurance Company in Canada: What Actually Matters | AO2: Is Group Life Insurance Enough? Work Coverage, Top-Ups and What Happens When You Leave | AP2: How Much Critical Illness Insurance Do I Need? | AQ2: Is Children's Life Insurance Worth It? Pros, Cons and Alternatives in Canada | AR2: Life Insurance for Stay-at-Home Parents: What Their Work Is Worth | AS2: Health Insurance for Early Retirees: Bridging the Gap Before 65 | AT2: Guaranteed-Issue vs Underwritten Health Insurance: Pre-Existing Conditions Explained | AU2: Joint vs Individual Life Insurance: What Couples Should Choose | AV2: Life Insurance With Depression or Anxiety in Canada: How Mental Health Is Underwritten | AW2: How to Convert Term Life Insurance to Permanent in Canada | AX2: 12 Life Insurance Myths Canadians Still Believe (and the Facts) | AY2: Funeral Insurance Waiting Periods: How the Two-Year Rule Works | AZ2: Life Insurance for Young Adults: Should You Buy in Your 20s? | BA2: Joint Last-to-Die Life Insurance: How Couples Cover Estate Taxes | BB2: Joint Mortgage Life Insurance: What Couples Need to Know Before They Sign | BC2: Life Insurance Rating Classes Explained: Preferred, Standard and Rated
A3: Priority (1 = do first) | B3: ='Topic Index'!I5 -> 1 | C3: ='Topic Index'!I6 -> 1 | D3: ='Topic Index'!I7 -> 1 | E3: ='Topic Index'!I8 -> 1 | F3: ='Topic Index'!I9 -> 1 | G3: ='Topic Index'!I10 -> 1 | H3: ='Topic Index'!I11 -> 1 | I3: ='Topic Index'!I12 -> 1 | J3: ='Topic Index'!I13 -> 1 | K3: ='Topic Index'!I14 -> 2 | L3: ='Topic Index'!I15 -> 2 | M3: ='Topic Index'!I16 -> 2 | N3: ='Topic Index'!I17 -> 2 | O3: ='Topic Index'!I18 -> 2 | P3: ='Topic Index'!I19 -> 2 | Q3: ='Topic Index'!I20 -> 2 | R3: ='Topic Index'!I21 -> 2 | S3: ='Topic Index'!I22 -> 2 | T3: ='Topic Index'!I23 -> 2 | U3: ='Topic Index'!I24 -> 2 | V3: ='Topic Index'!I25 -> 2 | W3: ='Topic Index'!I26 -> 2 | X3: ='Topic Index'!I27 -> 2 | Y3: ='Topic Index'!I28 -> 2 | Z3: ='Topic Index'!I29 -> 2 | AA3: ='Topic Index'!I30 -> 2 | AB3: ='Topic Index'!I31 -> 2 | AC3: ='Topic Index'!I32 -> 2 | AD3: ='Topic Index'!I33 -> 2 | AE3: ='Topic Index'!I34 -> 2 | AF3: ='Topic Index'!I35 -> 2 | AG3: ='Topic Index'!I36 -> 2 | AH3: ='Topic Index'!I37 -> 3 | AI3: ='Topic Index'!I38 -> 3 | AJ3: ='Topic Index'!I39 -> 3 | AK3: ='Topic Index'!I40 -> 3 | AL3: ='Topic Index'!I41 -> 3 | AM3: ='Topic Index'!I42 -> 3 | AN3: ='Topic Index'!I43 -> 3 | AO3: ='Topic Index'!I44 -> 3 | AP3: ='Topic Index'!I45 -> 3 | AQ3: ='Topic Index'!I46 -> 3 | AR3: ='Topic Index'!I47 -> 3 | AS3: ='Topic Index'!I48 -> 3 | AT3: ='Topic Index'!I49 -> 3 | AU3: ='Topic Index'!I50 -> 3 | AV3: ='Topic Index'!I51 -> 3 | AW3: ='Topic Index'!I52 -> 3 | AX3: ='Topic Index'!I53 -> 3 | AY3: ='Topic Index'!I54 -> 3 | AZ3: ='Topic Index'!I55 -> 3 | BA3: ='Topic Index'!I56 -> 3 | BB3: ='Topic Index'!I57 -> 3 | BC3: ='Topic Index'!I58 -> 3
A4: Traffic rank (of 54) | B4: ='Topic Index'!J5 -> 1 | C4: ='Topic Index'!J6 -> 2 | D4: ='Topic Index'!J7 -> 3 | E4: ='Topic Index'!J8 -> 3 | F4: ='Topic Index'!J9 -> 5 | G4: ='Topic Index'!J10 -> 5 | H4: ='Topic Index'!J11 -> 7 | I4: ='Topic Index'!J12 -> 20 | J4: ='Topic Index'!J13 -> 32 | K4: ='Topic Index'!J14 -> 8 | L4: ='Topic Index'!J15 -> 8 | M4: ='Topic Index'!J16 -> 8 | N4: ='Topic Index'!J17 -> 8 | O4: ='Topic Index'!J18 -> 8 | P4: ='Topic Index'!J19 -> 8 | Q4: ='Topic Index'!J20 -> 14 | R4: ='Topic Index'!J21 -> 14 | S4: ='Topic Index'!J22 -> 14 | T4: ='Topic Index'!J23 -> 14 | U4: ='Topic Index'!J24 -> 14 | V4: ='Topic Index'!J25 -> 14 | W4: ='Topic Index'!J26 -> 20 | X4: ='Topic Index'!J27 -> 20 | Y4: ='Topic Index'!J28 -> 20 | Z4: ='Topic Index'!J29 -> 20 | AA4: ='Topic Index'!J30 -> 20 | AB4: ='Topic Index'!J31 -> 26 | AC4: ='Topic Index'!J32 -> 26 | AD4: ='Topic Index'!J33 -> 26 | AE4: ='Topic Index'!J34 -> 26 | AF4: ='Topic Index'!J35 -> 26 | AG4: ='Topic Index'!J36 -> 26 | AH4: ='Topic Index'!J37 -> 32 | AI4: ='Topic Index'!J38 -> 32 | AJ4: ='Topic Index'!J39 -> 32 | AK4: ='Topic Index'!J40 -> 32 | AL4: ='Topic Index'!J41 -> 32 | AM4: ='Topic Index'!J42 -> 38 | AN4: ='Topic Index'!J43 -> 38 | AO4: ='Topic Index'!J44 -> 38 | AP4: ='Topic Index'!J45 -> 38 | AQ4: ='Topic Index'!J46 -> 38 | AR4: ='Topic Index'!J47 -> 38 | AS4: ='Topic Index'!J48 -> 38 | AT4: ='Topic Index'!J49 -> 38 | AU4: ='Topic Index'!J50 -> 38 | AV4: ='Topic Index'!J51 -> 38 | AW4: ='Topic Index'!J52 -> 38 | AX4: ='Topic Index'!J53 -> 49 | AY4: ='Topic Index'!J54 -> 49 | AZ4: ='Topic Index'!J55 -> 49 | BA4: ='Topic Index'!J56 -> 49 | BB4: ='Topic Index'!J57 -> 53 | BC4: ='Topic Index'!J58 -> 53
A5: Monthly searches (modelled) | B5: ='Topic Index'!E5 -> 1900 | C5: ='Topic Index'!E6 -> 1000 | D5: ='Topic Index'!E7 -> 880 | E5: ='Topic Index'!E8 -> 880 | F5: ='Topic Index'!E9 -> 720 | G5: ='Topic Index'!E10 -> 720 | H5: ='Topic Index'!E11 -> 590 | I5: ='Topic Index'!E12 -> 320 | J5: ='Topic Index'!E13 -> 210 | K5: ='Topic Index'!E14 -> 480 | L5: ='Topic Index'!E15 -> 480 | M5: ='Topic Index'!E16 -> 480 | N5: ='Topic Index'!E17 -> 480 | O5: ='Topic Index'!E18 -> 480 | P5: ='Topic Index'!E19 -> 480 | Q5: ='Topic Index'!E20 -> 390 | R5: ='Topic Index'!E21 -> 390 | S5: ='Topic Index'!E22 -> 390 | T5: ='Topic Index'!E23 -> 390 | U5: ='Topic Index'!E24 -> 390 | V5: ='Topic Index'!E25 -> 390 | W5: ='Topic Index'!E26 -> 320 | X5: ='Topic Index'!E27 -> 320 | Y5: ='Topic Index'!E28 -> 320 | Z5: ='Topic Index'!E29 -> 320 | AA5: ='Topic Index'!E30 -> 320 | AB5: ='Topic Index'!E31 -> 260 | AC5: ='Topic Index'!E32 -> 260 | AD5: ='Topic Index'!E33 -> 260 | AE5: ='Topic Index'!E34 -> 260 | AF5: ='Topic Index'!E35 -> 260 | AG5: ='Topic Index'!E36 -> 260 | AH5: ='Topic Index'!E37 -> 210 | AI5: ='Topic Index'!E38 -> 210 | AJ5: ='Topic Index'!E39 -> 210 | AK5: ='Topic Index'!E40 -> 210 | AL5: ='Topic Index'!E41 -> 210 | AM5: ='Topic Index'!E42 -> 170 | AN5: ='Topic Index'!E43 -> 170 | AO5: ='Topic Index'!E44 -> 170 | AP5: ='Topic Index'!E45 -> 170 | AQ5: ='Topic Index'!E46 -> 170 | AR5: ='Topic Index'!E47 -> 170 | AS5: ='Topic Index'!E48 -> 170 | AT5: ='Topic Index'!E49 -> 170 | AU5: ='Topic Index'!E50 -> 170 | AV5: ='Topic Index'!E51 -> 170 | AW5: ='Topic Index'!E52 -> 170 | AX5: ='Topic Index'!E53 -> 140 | AY5: ='Topic Index'!E54 -> 140 | AZ5: ='Topic Index'!E55 -> 140 | BA5: ='Topic Index'!E56 -> 140 | BB5: ='Topic Index'!E57 -> 110 | BC5: ='Topic Index'!E58 -> 110
A6: Primary keyword | B6: mortgage insurance canada | C6: what is term life insurance | D6: how does life insurance work | E6: types of life insurance canada | F6: is life insurance worth it | G6: whole life insurance cost | H6: instant life insurance canada | I6: health insurance after losing job canada | J6: declined for life insurance | K6: is critical illness insurance worth it | L6: family life insurance | M6: life insurance with pre existing conditions | N6: life insurance medical exam | O6: term 100 life insurance | P6: 20 year term life insurance | Q6: funeral insurance for seniors | R6: life insurance beneficiary canada | S6: life insurance over 70 | T6: life insurance over 50 | U6: what happens when term life insurance expires | V6: whole life vs universal life insurance | W6: how to claim life insurance canada | X6: life insurance riders | Y6: what does life insurance not cover | Z6: life insurance for diabetics | AA6: participating whole life insurance | AB6: what affects life insurance rates | AC6: life insurance after cancer | AD6: buy term and invest the difference | AE6: life insurance for estate planning canada | AF6: decreasing term life insurance | AG6: how does universal life insurance work | AH6: funeral insurance no medical | AI6: life insurance for new parents | AJ6: buy sell agreement life insurance | AK6: life insurance after heart attack | AL6: how do life insurance companies check medical history | AM6: life insurance broker vs agent | AN6: how to choose a life insurance company | AO6: is group life insurance enough | AP6: how much critical illness insurance do i need | AQ6: is children's life insurance worth it | AR6: life insurance for stay at home parent | AS6: health insurance for early retirees canada | AT6: guaranteed issue health insurance | AU6: joint vs individual life insurance | AV6: life insurance with depression | AW6: convert term life insurance to permanent | AX6: life insurance myths | AY6: funeral insurance waiting period | AZ6: life insurance for young adults | BA6: joint last to die life insurance | BB6: joint mortgage life insurance | BC6: life insurance rating classes
A7: SEO title tag | B7: Mortgage Insurance in Canada: CMHC vs Mortgage Life Cover | C7: What Is Term Life Insurance? How It Works in Canada | D7: How Does Life Insurance Work in Canada? A Simple Guide | E7: Types of Life Insurance in Canada: Every Option Explained | F7: Is Life Insurance Worth It in Canada? A Plain Answer | G7: Whole Life Insurance Cost in Canada: Example Premiums | H7: Instant Life Insurance in Canada: Online Options Compared | I7: Health Insurance After Losing Your Job in Canada | J7: Declined for Life Insurance? What to Do Next (Canada) | K7: Is Critical Illness Insurance Worth It? Canada Guide | L7: Family Life Insurance in Canada: How to Cover Everyone | M7: Life Insurance With Pre-Existing Conditions in Canada | N7: Life Insurance Medical Exam: What to Expect in Canada | O7: Term 100 Life Insurance in Canada: How It Works | P7: 20 Year Term Life Insurance vs 10 and 30-Year Terms | Q7: Funeral Insurance for Seniors in Canada: Options by Age | R7: Choosing a Life Insurance Beneficiary in Canada | S7: Life Insurance Over 70 in Canada: Options and Age Limits | T7: Life Insurance Over 50 in Canada: Costs and Options | U7: What Happens When Term Life Insurance Expires? | V7: Whole Life vs Universal Life Insurance in Canada | W7: How to Claim Life Insurance in Canada: Step by Step | X7: Life Insurance Riders in Canada: What Each Add-On Does | Y7: What Does Life Insurance Not Cover? Canadian Exclusions | Z7: Life Insurance for Diabetics in Canada: Type 1 and 2 | AA7: Participating Whole Life Insurance and Cash Value | AB7: What Affects Life Insurance Rates in Canada? Key Factors | AC7: Life Insurance After Cancer in Canada: Options by Stage | AD7: Buy Term and Invest the Difference in Canada: Does It Work? | AE7: Life Insurance for Estate Planning in Canada: A Guide | AF7: Decreasing Term Life Insurance vs Level Term (Canada) | AG7: How Does Universal Life Insurance Work in Canada? | AH7: Funeral Insurance With No Medical Exam: How to Qualify | AI7: Life Insurance for New Parents in Canada: A Clear Plan | AJ7: Buy-Sell Agreement Life Insurance: Owner's Guide (Canada) | AK7: Life Insurance After a Heart Attack in Canada: Options | AL7: How Life Insurance Companies Check Your Medical History | AM7: Life Insurance Broker vs Agent vs Bank: Where to Buy | AN7: How to Choose a Life Insurance Company in Canada | AO7: Is Group Life Insurance Enough? Work Cover vs Your Own | AP7: How Much Critical Illness Insurance Do I Need? | AQ7: Is Children's Life Insurance Worth It? Pros and Cons | AR7: Life Insurance for Stay-at-Home Parents in Canada | AS7: Health Insurance for Early Retirees in Canada (Under 65) | AT7: Guaranteed Issue Health Insurance vs Underwritten | AU7: Joint vs Individual Life Insurance for Couples (Canada) | AV7: Life Insurance With Depression or Anxiety in Canada | AW7: Convert Term Life Insurance to Permanent: How It Works | AX7: 12 Life Insurance Myths Canadians Still Believe | AY7: Funeral Insurance Waiting Periods: The Two-Year Rule | AZ7: Life Insurance for Young Adults: Should You Buy in Your 20s? | BA7: Joint Last-to-Die Life Insurance: Estate Tax Guide | BB7: Joint Mortgage Life Insurance: A Guide for Couples | BC7: Life Insurance Rating Classes: Preferred to Rated
A8: Title length (target 45–60) | B8: =LEN(B7) -> 57 | C8: =LEN(C7) -> 51 | D8: =LEN(D7) -> 54 | E8: =LEN(E7) -> 57 | F8: =LEN(F7) -> 52 | G8: =LEN(G7) -> 53 | H8: =LEN(H7) -> 57 | I8: =LEN(I7) -> 48 | ... BC8: =LEN(BC7) -> 49
A9: Meta description | B9: Mortgage insurance in Canada explained: CMHC default insurance vs mortgage life insurance, who each protects, what is mandatory and when term life fits. | C9: What is term life insurance? How 10, 20 and 30-year terms work in Canada, what drives the price, renewal and conversion, pros and cons, and who it suits. | D9: How does life insurance work in Canada? Premiums, death benefits, beneficiaries, term vs permanent, how insurers price risk, taxes and how a claim gets paid. | E9: Types of life insurance in Canada: term, term to 100, whole, universal, no-medical, joint, group and creditor cover, with a comparison table and tips. | F9: Is life insurance worth it in Canada? Who usually needs it, who may not, what to check before cancelling, cheaper ways to stay covered and a self-test. | G9: Whole life insurance cost in Canada: example premiums by age and amount, lifetime vs 20-pay, par vs non-par, and ways to make permanent cover affordable. | H9: Instant life insurance in Canada: how online approval works, issue ages and maximums, the health questions, when instant costs more and how to apply safely. | I9: Health insurance after losing your job in Canada: how long group benefits last, no-medical conversion plans, new plan costs, a spouse's plan and a checklist. | J9: Declined for life insurance in Canada? What declined, postponed and rated mean, how to get the reason, the MIB, reapplying and no-medical options. | K9: Is critical illness insurance worth it in Canada? Costs health plans don't pay, who benefits most, when to skip it and a five-question decision test. | L9: Family life insurance in Canada: why one policy rarely covers everyone, options for parents, couples and children, a comparison table and how to buy. | M9: Life insurance with pre-existing conditions in Canada: how underwriters assess health issues, why disclosure matters, no-medical options and better odds. | N9: Life insurance medical exam in Canada: what the paramedical exam involves, blood and urine tests, doctor reports, underwriting time and how to prepare. | O9: Term 100 life insurance in Canada: lifetime cover, level premiums and no cash value. How it compares with whole and universal life, what it costs, who it suits. | P9: 20 year term life insurance vs 10 and 30-year terms in Canada: price differences, matching your mortgage and kids, laddering and a term length decision table. | Q9: Funeral insurance for seniors in Canada: options at 60, 70 and 80, simplified vs guaranteed issue, labelled cost estimates by age and replacing group life. | R9: Choosing a life insurance beneficiary in Canada: revocable vs irrevocable, minor children, contingent and multiple beneficiaries, your estate and Quebec rules. | S9: Life insurance over 70 in Canada: policies you can still buy, age limits at 75, 80 and 85, no-medical and guaranteed issue options, costs and if it's worth it. | T9: Life insurance over 50 in Canada: example rates by age and amount, term vs permanent, no-medical options, health factors after 50 and how much cover you need. | U9: What happens when term life insurance expires in Canada: renewal rates, converting to permanent without a medical, buying a new policy or letting it lapse. | V9: Whole life vs universal life insurance in Canada: guarantees, cash value, investment options, level vs YRT cost of insurance, tax rules and who each one suits. | W9: How to claim life insurance in Canada: find the policy, gather documents, submit forms, typical payout times, the two-year rule and denied claims. | X9: Life insurance riders in Canada: waiver of premium, child term, guaranteed insurability, critical illness and accidental death, with costs and who each suits. | Y9: What life insurance does not cover in Canada: the suicide clause, the two-year contestability rule, misrepresentation, lapses, accidental death limits. | Z9: Life insurance for diabetics in Canada: how type 1 or 2, A1C, age at diagnosis and complications affect rates, no-medical options and an application checklist. | AA9: Participating whole life insurance in Canada: how dividends and cash value grow, surrender value, policy loans, paid-up additions and when a par policy fits. | AB9: What affects life insurance rates in Canada: age, sex, health, smoking, family history, job, hobbies, driving record, amount and term, and how quotes work. | AC9: Life insurance after cancer in Canada: how type, stage and time since treatment affect approval, typical waiting periods, no-medical options and records. | AD9: Buy term and invest the difference, or whole life? A worked Canadian TFSA example, the discipline risk, taxes and the cases where permanent cover wins. | AE9: Life insurance for estate planning in Canada: covering tax on capital gains at death, keeping the cottage, equalising inheritances, charity and probate. | AF9: Decreasing term life insurance vs level term in Canada: how each works, the cost over a 25-year mortgage, where lender insurance fits and which to choose. | AG9: How universal life insurance works in Canada: cost of insurance, the investment account, flexible deposits, tax-exempt growth, the risks and how to buy. | AH9: Funeral insurance with no medical exam in Canada: the health questions simplified plans ask, when guaranteed acceptance fits and how health changes cost. | AI9: Life insurance for new parents in Canada: how much cover a family with a baby needs, insuring a stay-at-home parent, parental leave and a checklist. | AJ9: Buy-sell agreement life insurance in Canada: funding a partner buyout, cross-purchase vs corporate-owned policies, the capital dividend account and sizing. | AK9: Life insurance after a heart attack in Canada: waiting times, stents and bypass, the tests underwriters ask for and no-medical options while you recover. | AL9: How life insurance companies check your medical history in Canada: health questions, the MIB, doctor reports, prescriptions, exams and the two-year rule. | AM9: Life insurance broker vs agent vs bank vs online in Canada: insurer choice, advice, underwriting help, how each is paid and the questions to ask before you buy. | AN9: How to choose a life insurance company in Canada: financial strength, claims practices, Assuris protection, complaint records, products and service. | AO9: Is group life insurance enough in Canada? What work plans pay, optional top-ups, what happens when you leave or are laid off, conversion and sizing. | AP9: How much critical illness insurance do you need in Canada? A three-step worksheet for income, uncovered costs and debts, plus term choices and group cover. | AQ9: Is children's life insurance worth it in Canada? What it covers, the case for and against, child riders and RESPs as alternatives, and grandparent policies. | AR9: Life insurance for stay-at-home parents in Canada: what unpaid work costs to replace, how much cover to buy, term vs permanent and what it costs. | AS9: Health insurance for early retirees in Canada: retiree benefits, converting a group plan, plan costs from 55 to 64, drug coverage before 65 and travel cover. | AT9: Guaranteed issue health insurance vs underwritten plans in Canada: pre-existing conditions, drug coverage limits, conversion plans and how to choose. | AU9: Joint vs individual life insurance for Canadian couples: first-to-die vs last-to-die, cost, the single payout, separation and a couple's decision guide. | AV9: Life insurance with depression or anxiety in Canada: what underwriters ask, how severity, medication and time off work count, and how to apply with confidence. | AW9: How to convert term life insurance to permanent in Canada: conversion deadlines, no-medical eligibility, which plans qualify and what the new premium costs. | AX9: Twelve life insurance myths debunked for Canadians: cost, medical exams, group cover, stay-at-home parents, age, health, investing and salary rules. | AY9: Funeral insurance waiting periods in Canada: how the two-year rule and graded benefits work, accidental death cover and how to avoid a waiting period. | AZ9: Life insurance for young adults in Canada: when buying in your 20s makes sense, locking in rates and insurability, what it costs, and when you can safely wait. | BA9: Joint last-to-die life insurance in Canada: how it pays at the second death, covering the tax on a cottage or RRIF, cost vs two policies and who it suits. | BB9: Joint mortgage life insurance in Canada pays once: what that means for the surviving partner, separation and refinancing, and how two term policies compare. | BC9: Life insurance rating classes in Canada: preferred plus, preferred, standard and table ratings, how BMI, blood pressure and family history count, and cost.
A10: Meta length (target 140–160) | B10: =LEN(B9) -> 152 | C10: =LEN(C9) -> 153 | D10: =LEN(D9) -> 157 | E10: =LEN(E9) -> 150 | F10: =LEN(F9) -> 151 | G10: =LEN(G9) -> 153 | H10: =LEN(H9) -> 156 | I10: =LEN(I9) -> 157 | ... BC10: =LEN(BC9) -> 155
A11: URL | B11: https://instasure.ca/guides/mortgage-insurance-canada-explained/ | C11: https://instasure.ca/guides/what-is-term-life-insurance-canada/ | D11: https://instasure.ca/guides/how-does-life-insurance-work-canada/ | E11: https://instasure.ca/guides/types-of-life-insurance-canada/ | F11: https://instasure.ca/guides/is-life-insurance-worth-it-canada/ | G11: https://instasure.ca/guides/whole-life-insurance-cost-canada/ | H11: https://instasure.ca/guides/instant-life-insurance-canada/ | I11: https://instasure.ca/guides/health-insurance-after-losing-job/ | J11: https://instasure.ca/guides/declined-for-life-insurance-what-next/ | K11: https://instasure.ca/guides/is-critical-illness-insurance-worth-it/ | L11: https://instasure.ca/guides/family-life-insurance-canada/ | M11: https://instasure.ca/guides/life-insurance-pre-existing-conditions-canada/ | N11: https://instasure.ca/guides/life-insurance-medical-exam-application/ | O11: https://instasure.ca/guides/term-100-life-insurance-canada/ | P11: https://instasure.ca/guides/10-20-30-year-term-life-insurance/ | Q11: https://instasure.ca/guides/funeral-insurance-for-seniors-canada/ | R11: https://instasure.ca/guides/life-insurance-beneficiary-canada/ | S11: https://instasure.ca/guides/life-insurance-over-70-canada/ | T11: https://instasure.ca/guides/life-insurance-over-50-canada/ | U11: https://instasure.ca/guides/what-happens-when-term-life-insurance-expires/ | V11: https://instasure.ca/guides/whole-life-vs-universal-life-insurance/ | W11: https://instasure.ca/guides/how-to-make-a-life-insurance-claim-canada/ | X11: https://instasure.ca/guides/life-insurance-riders-canada/ | Y11: https://instasure.ca/guides/what-does-life-insurance-not-cover/ | Z11: https://instasure.ca/guides/life-insurance-with-diabetes-canada/ | AA11: https://instasure.ca/guides/participating-whole-life-insurance-cash-value/ | AB11: https://instasure.ca/guides/what-affects-life-insurance-rates/ | AC11: https://instasure.ca/guides/life-insurance-after-cancer-canada/ | AD11: https://instasure.ca/guides/buy-term-and-invest-the-difference-canada/ | AE11: https://instasure.ca/guides/life-insurance-estate-planning-canada/ | AF11: https://instasure.ca/guides/decreasing-term-vs-level-term-life-insurance/ | AG11: https://instasure.ca/guides/how-universal-life-insurance-works/ | AH11: https://instasure.ca/guides/funeral-insurance-no-medical-exam/ | AI11: https://instasure.ca/guides/life-insurance-for-new-parents-canada/ | AJ11: https://instasure.ca/guides/buy-sell-agreement-life-insurance-canada/ | AK11: https://instasure.ca/guides/life-insurance-after-heart-attack-canada/ | AL11: https://instasure.ca/guides/how-life-insurance-companies-check-medical-history/ | AM11: https://instasure.ca/guides/life-insurance-broker-vs-agent-vs-bank/ | AN11: https://instasure.ca/guides/how-to-choose-a-life-insurance-company/ | AO11: https://instasure.ca/guides/is-group-life-insurance-enough/ | AP11: https://instasure.ca/guides/how-much-critical-illness-insurance-do-i-need/ | AQ11: https://instasure.ca/guides/is-childrens-life-insurance-worth-it/ | AR11: https://instasure.ca/guides/life-insurance-for-stay-at-home-parents/ | AS11: https://instasure.ca/guides/health-insurance-for-early-retirees/ | AT11: https://instasure.ca/guides/guaranteed-issue-vs-underwritten-health-insurance/ | AU11: https://instasure.ca/guides/joint-life-insurance-vs-two-policies/ | AV11: https://instasure.ca/guides/life-insurance-depression-anxiety-canada/ | AW11: https://instasure.ca/guides/convert-term-life-insurance-to-permanent/ | AX11: https://instasure.ca/guides/life-insurance-myths-canada/ | AY11: https://instasure.ca/guides/funeral-insurance-waiting-period/ | AZ11: https://instasure.ca/guides/life-insurance-for-young-adults-canada/ | BA11: https://instasure.ca/guides/joint-last-to-die-life-insurance/ | BB11: https://instasure.ca/guides/joint-mortgage-life-insurance/ | BC11: https://instasure.ca/guides/life-insurance-rating-classes-canada/
A12: Secondary keywords (H2s, FAQ, body) | B12: cmhc insurance vs mortgage life insurance, is mortgage life insurance mandatory, mortgage protection insurance, mortgage default insurance, mortgage loan insurance | C12: how does term life insurance work, term life insurance canada, types of term life insurance, term life insurance pros and cons, yearly renewable term | D12: how does life insurance work in canada, life insurance explained, what is life insurance, how do life insurance payouts work, life insurance basics | E12: different types of life insurance, term vs permanent life insurance, term to 100 life insurance, what is permanent life insurance, variable life insurance canada | F12: do i need life insurance, who needs life insurance, life insurance for single people, do i need life insurance if i have no kids, should i cancel life insurance | G12: whole life insurance rates canada, limited pay whole life insurance, 20 pay whole life cost, whole life insurance cost by age, permanent life insurance cost | H12: buy life insurance online, instant approval life insurance, same day life insurance canada, online term life insurance canada, life insurance without meeting an advisor | I12: health insurance between jobs canada, group benefits conversion plan, what happens to benefits when laid off, continue health insurance after leaving job, individual health plan no medical | J12: denied life insurance canada, life insurance postponed, reapply after life insurance decline, high risk life insurance, anonymous pre-underwriting | K12: what is critical illness insurance, should i get critical illness insurance, critical illness insurance pros and cons, do i need critical illness insurance, critical illness insurance with group benefits | L12: family life insurance canada, life insurance for the whole family, life insurance for parents and children, family life insurance plan, life insurance for young families | M12: life insurance with health issues, how to get life insurance with health problems, high risk life insurance canada, life insurance for chronic illness, no medical life insurance pre existing conditions | N12: what is asked on a life insurance application, paramedical exam, life insurance blood test, attending physician statement, how long does life insurance underwriting take | O12: term to 100 life insurance, term 100 vs whole life, term 100 cost, permanent life insurance without cash value, term 100 canada | P12: 10 year term life insurance, 30 year term life insurance, how long should term life insurance be, term length for mortgage, term to 65 | Q12: funeral insurance over 70, funeral insurance over 80, final expense insurance for seniors, burial insurance for seniors, life insurance for seniors over 75 | R12: revocable vs irrevocable beneficiary, minor child beneficiary life insurance, contingent beneficiary, multiple beneficiaries life insurance, naming estate as beneficiary | S12: life insurance age limit canada, life insurance over 75, life insurance for seniors over 80, is life insurance worth it after 70, guaranteed issue life insurance for seniors | T12: life insurance cost for 50 year old, term life insurance over 50, no medical life insurance at 50, life insurance for 55 year old, life insurance at 60 canada | U12: term life insurance renewal, convert term life to whole life, term conversion deadline, renewable term life insurance canada, end of term life insurance | V12: universal life insurance canada, universal life insurance pros and cons, level vs yrt cost of insurance, is universal life insurance worth it, variable life insurance canada | W12: life insurance claim process, how long does a life insurance payout take, life insurance claim documents, why life insurance claims are denied, life insurance contestability period | X12: waiver of premium rider, child term rider, guaranteed insurability rider, critical illness rider vs standalone, accidental death benefit rider | Y12: life insurance exclusions canada, life insurance suicide clause canada, life insurance contestability period, does life insurance cover overdose, life insurance fine print | Z12: life insurance type 2 diabetes canada, life insurance type 1 diabetes, insulin dependent life insurance, a1c life insurance, no medical life insurance diabetes | AA12: cash value life insurance canada, cash surrender value, whole life dividends, paid-up additions, par vs non-par whole life, life insurance as savings | AB12: how are life insurance quotes calculated, life insurance rates canada, factors affecting life insurance premiums, why are life insurance quotes different, how to lower life insurance premiums | AC12: life insurance for cancer survivors canada, life insurance with cancer, life insurance in remission, stage 4 cancer life insurance, guaranteed issue after cancer | AD12: is whole life insurance a good investment, term vs whole life investment, life insurance as an investment canada, whole life vs tfsa, cash value vs investing | AE12: deemed disposition at death canada, capital gains tax on cottage at death, life insurance for inheritance, best way to leave money to family, life insurance probate | AF12: decreasing term life insurance canada, level term life insurance, increasing term life insurance, mortgage term life insurance, reducing term insurance | AG12: universal life insurance explained, universal life insurance tax, universal life cash value, universal life insurance canada, what is universal life insurance | AH12: no medical funeral insurance, final expense insurance no medical exam, guaranteed acceptance funeral insurance, simplified issue funeral insurance, funeral insurance with health conditions | AI12: life insurance for young parents, life insurance after having a baby, how much life insurance with kids, life insurance during parental leave, life insurance for young families | AJ12: shareholder agreement life insurance, business partner life insurance, cross-purchase vs corporate redemption, capital dividend account life insurance, joint first to die business partners | AK12: life insurance heart disease canada, life insurance with a heart condition, life insurance after stent, life insurance after bypass surgery, atrial fibrillation life insurance | AL12: mib life insurance canada, attending physician statement, life insurance medical records, can life insurance see my medical records, life insurance misrepresentation | AM12: independent life insurance broker canada, captive agent vs broker, buying life insurance from your bank, buy life insurance online vs advisor, how are life insurance advisors paid | AN12: most reputable life insurance companies canada, life insurance company ratings, assuris protection, life insurance claim settlement ratio canada, can i trust online insurance reviews | AO12: group life insurance vs individual, group life insurance conversion, life insurance when you leave your job, optional group life top up, employer life insurance canada | AP12: critical illness insurance calculator, critical illness coverage amount, critical illness insurance term length, term 10 vs term 100 critical illness, critical illness insurance canada | AQ12: children's life insurance, life insurance for kids canada, child term rider, whole life for children, grandparent buying life insurance for grandchild | AR12: stay at home mom life insurance, stay at home dad life insurance, life insurance for non working spouse, spousal life insurance canada, how much life insurance for a stay at home mom | AS12: retiree health benefits canada, health insurance after retirement before 65, retiree health and dental plan, post retirement health insurance, health insurance for retirees canada | AT12: health insurance pre existing conditions canada, no medical health insurance canada, guaranteed approval health insurance, underwritten health plan, pre-existing condition exclusion health plan | AU12: joint life insurance, first to die life insurance, joint last to die life insurance, life insurance for couples canada, joint life insurance divorce | AV12: life insurance with anxiety canada, mental health life insurance, antidepressants life insurance, adhd life insurance, does therapy affect life insurance | AW12: term life conversion option, convert term to whole life, term conversion deadline, conversion privilege life insurance, convertible term life insurance | AX12: life insurance misconceptions, is life insurance a waste of money, do i need life insurance, life insurance facts canada, common life insurance mistakes | AY12: final expense insurance waiting period, guaranteed issue waiting period, graded death benefit, funeral insurance two year rule, accidental death funeral insurance | AZ12: life insurance in your 20s, should i get life insurance at 25, life insurance for students canada, cheap life insurance for young adults, too young for life insurance | BA12: last to die life insurance canada, joint second to die, life insurance for estate taxes, cottage capital gains life insurance, joint survivorship life insurance | BB12: mortgage insurance for couples, joint mortgage insurance pays once, mortgage life insurance after divorce, two term policies vs joint mortgage insurance, co-borrower mortgage insurance | BC12: preferred vs standard life insurance, table rating life insurance, life insurance build chart bmi, life insurance underwriting classes, rated life insurance policy
A13: Value asset (why it ranks and gets cited) | B13: A two-column comparison graphic (default insurance vs life cover: who pays, who benefits, when it pays, required or optional) and a signing-day question card. | C13: A worked timeline for one 35-year-old buying 20-year term: premium schedule from the Instasure model, the renewal-rate jump at year 21 and the conversion deadline, shown as a labelled chart and table (estimates, dated). | D13: A one-screen diagram of a policy's life cycle (apply, underwriting, premiums, claim, tax-free payout) with the roles of owner, life insured and beneficiary, plus a plain-language glossary box. | E13: A one-screen comparison table of seven policy types (term 10/20/30, term to 100, participating whole, universal, simplified issue, guaranteed issue, group) with columns for duration, cash value, premium pattern, medical underwriting and typical use, plus a five-question decision tree. | F13: A six-question self-test that scores need (dependants, debts, income reliance, estate goals) with result bands, plus a 'before you cancel' checklist tied to 2026 reports of Canadians cutting insurance. | G13: A dated example-premium table for $100K and $250K whole life at ages 30, 45 and 60 across lifetime, 20-pay and 10-pay options from the Instasure model. | H13: A dated comparison table of direct-to-consumer products (Sun Life Go Term, Go Simplified, Go Guaranteed, Manulife CoverMe and others) with issue ages, maximum coverage, number of health questions, refund period and time to coverage, each cell sourced. | I13: A 30-day action checklist with deadlines and a comparison table of conversion plan vs underwritten plan vs guaranteed-issue plan. | J13: A step-by-step recovery plan (get the reason, request records, fix errors, shop with a desk advisor, fallback options) and a decision tree from decline reason to next step. | K13: A five-question decision tree plus a worked example comparing a lump-sum benefit with six months of lost income and uncovered costs for a stated two-income household. | L13: A comparison table of family coverage options (term per parent, joint, whole or universal, mortgage, children's policy, child rider) by who is covered, payout, cost and best use, plus a worked family example. | M13: A condition-by-condition table (diabetes, cancer history, heart, blood pressure, mental health, other chronic conditions) showing the usual route (fully underwritten, simplified, guaranteed) and what records help, reviewed by the Medical underwriting desk. | N13: An exam-day preparation checklist and an underwriting timeline graphic (application to approval) with typical step durations, plus the question categories found on a standard application. | O13: A side-by-side table (term 100, participating whole life, universal life, 30-year term) by premium, cash value, guarantees and best use, plus labelled example premiums for one profile from the Instasure model. | P13: A decision table matching term length to life-stage triggers (youngest child's age, mortgage years left, planned retirement date) plus a price-by-term comparison for one example profile from the Instasure model. | Q13: A dated table of Instasure example estimates for $10,000 and $15,000 at ages 60, 65, 70, 75 and 80 (female and male non-smokers), labelled with profile and month, plus a pre-purchase checklist. | R13: A beneficiary-designation decision tree and a table comparing options (spouse, minor child with trustee, insurance trust, estate, charity) by payout speed, probate, creditor protection and control. | S13: An issue-age table by product type (term 10/20, term to 100, whole life, simplified issue, guaranteed issue, final expense) with typical maximum issue ages and coverage caps, each verified against insurer guides and dated. | T13: A dated age-50 rate table (sex × amount × term × smoker status) and a side-by-side of fully underwritten vs simplified-issue estimates for the same profile. | U13: A five-year pre-expiry checklist and a three-way comparison (renew, convert, reapply) with a worked example of renewal vs new-policy cost for a 55-year-old from the Instasure model. | V13: A side-by-side table (premium flexibility, guarantees, cash value, investment risk, cost-of-insurance type, typical fit) and a worked example showing how a UL policy can lapse when returns fall short. | W13: A printable claim checklist (documents by situation: death in Canada, death abroad, accidental death) and a timeline graphic from notification to payout, with OLHI escalation steps. | X13: A rider checklist table showing what each rider pays, typical eligibility, who it suits, red flags and a 'skip it if' column. | Y13: An exclusions table (exclusion, how long it applies, what is paid instead, how to avoid the problem) with the source of each rule, plus a "read before you sign" checklist. | Z13: An underwriting factor matrix for diabetes (type, diagnosis age, A1C band, complications) showing likely outcome ranges, reviewed by the medical underwriting desk, plus a document checklist. | AA13: An annotated sample policy illustration (guaranteed vs non-guaranteed columns) with plain-language callouts, plus a glossary box of participating-policy terms. | AB13: A factor table (each rating factor, how insurers check it, how much it can move the price as a labelled model example, what you can change) built from the Instasure model. | AC13: A cancer-type table (skin, breast, prostate, thyroid, colon, blood cancers) with typical postponement periods and post-remission outcomes, reviewed by the medical underwriting desk, plus a bridge-coverage plan. | AD13: A worked 30-year example (term plus TFSA contributions vs participating whole life) with every assumption stated (premiums from the Instasure model, a stated return range, no tax advice), plus a "which approach fits" table. | AE13: A worked example estimating the deemed-disposition tax on a cottage and a RRIF for a couple, then sizing a joint last-to-die policy to cover it (assumptions and CRA sources stated). | AF13: A benefit-over-time chart (decreasing term, level term, lender balance-based cover) for one $500,000 mortgage, with model cost estimates. | AG13: A diagram of one universal life policy over 20 years (deposits in, cost of insurance out, account value) with level vs YRT shown side by side, plus a step-by-step buying checklist. | AH13: A sample of typical simplified-issue question types (described, not copied from an insurer) and a cost comparison of simplified vs guaranteed issue from the quote engine tiers, labelled. | AI13: A worked example for a family with a newborn (income replacement, childcare replacement cost, mortgage) and a one-page new-parent checklist covering will, guardian, beneficiary and coverage. | AJ13: A structure comparison table (cross-purchase, promissory note, corporate redemption, hybrid) with tax notes, plus a worked two-partner example sizing coverage to a stated valuation. | AK13: A cardiac-event timeline (0–6 months, 6–12 months, 1–2 years, 2+ years) with typical options at each stage, plus a list of cardiology reports to request, desk-reviewed. | AL13: A flow diagram from application to decision showing each information source (application, MIB, doctor reports, prescription records, exam results) and when consent is given, plus a "what to have ready" checklist. | AM13: A channel comparison table (insurer choice, advice, underwriting help, cost, payment model, after-sale service) and a seven-question checklist to ask any seller. | AN13: A checklist scorecard (financial strength, Assuris coverage, complaint route, conversion options, underwriting flexibility, service) the reader can apply to any insurer, with the source for each item. No ranking until a review method is published. | AO13: A group-vs-individual comparison table and a worked layoff scenario showing coverage before and after a job loss, with a conversion-window checklist (deadline verified per plan). | AP13: A fill-in sizing worksheet (income gap + uncovered costs + debts − group cover) with a worked family example, and an embedded instant estimate pre-filled with the resulting amount. | AQ13: A 25-year comparison of three approaches for one child (whole life policy, child term rider, investing the same premium in an RESP or TFSA), with assumptions stated and labelled hypothetical. | AR13: A replacement-cost worksheet (childcare, household work, transport, lost income if the working parent cuts hours) with a worked example using cited childcare costs, sized into a term amount and length. | AS13: Year-by-year budget template from retirement to 65 with modelled plan premiums and out-of-pocket estimates, plus a province table of the age when public drug coverage for seniors begins. | AT13: Comparison table of plan routes (guaranteed issue, underwritten, conversion) by health questions, drug limits, maximums and cost, with a worked example for a person on a monthly maintenance drug. | AU13: A cost-and-payout comparison for one example couple (joint first-to-die vs two term policies vs joint last-to-die) from the Instasure model, plus a separation scenario table. | AV13: A severity-and-stability table showing typical outcomes and the questionnaire items insurers use, reviewed by the medical underwriting desk, with a support-resources box (9-8-8 suicide crisis line). | AW13: A conversion timeline for one example policy (purchase, conversion deadline, renewal) and a table comparing full conversion, partial conversion and a new policy by health questions, premium and coverage length. | AX13: A myth-vs-fact table with a source or labelled model example for every fact, plus one example premium table by age from the Instasure model to answer "too expensive". | AY13: A year-by-year table showing what a typical graded or limited-benefit policy pays (refund of premiums, with or without interest, or the full benefit) versus a simplified-issue policy, flagged as typical structures to verify. | AZ13: A "buy now or wait" decision table by situation (no debts, co-signed loans, partner, mortgage, family history) with labelled example premiums at 25, 30 and 35 from the Instasure model. | BA13: A worked example for one couple (cottage gain and RRIF balance at the second death, estimated tax, policy sized to cover it) with every assumption stated, reviewed against CRA rules. | BB13: A scenario table (one partner dies, both die, separation, refinance, switching lenders) showing outcomes under joint lender cover vs two term policies. | BC13: A rating-class price impact table for one profile (preferred plus through table 4) from the Instasure model and an illustrative explanation of build-chart bands (no insurer's proprietary chart reproduced).
A14: Call to action | B14: Mortgage protection calculator (/calculators/mortgage-protection/) | C14: Instant term life estimate (/quote/) | D14: Instant life insurance estimate (/quote/life-insurance/) | E14: Instant life insurance estimate (/quote/) | F14: Life insurance needs calculator (/calculators/life-insurance-needs/) | G14: Instant life insurance estimate (/quote/) | H14: Instant life insurance estimate (/quote/) | I14: Instant health & dental estimate (/health-dental-insurance/) | J14: Request a specialist call: Medical underwriting desk (/life-insurance/medical-conditions/) | K14: Instant critical illness estimate (/critical-illness-insurance/) | L14: Life insurance needs calculator (/calculators/life-insurance-needs/) | M14: Request a specialist call: Medical underwriting desk (/life-insurance/medical-conditions/) | N14: Request a specialist call: Medical underwriting desk (/life-insurance/medical-conditions/) | O14: Instant life insurance estimate (/quote/life-insurance/) | P14: Instant term life estimate (/quote/) | Q14: Funeral expense estimate, from about $1 a day for the example profile (/life-insurance/funeral-expense/); Request a specialist call: Funeral expense desk | R14: Book a policy review with a licensed advisor (/advisors/) | S14: Instant seniors life insurance estimate (/quote/) | T14: Instant life insurance estimate (/quote/) | U14: Book a policy review with a licensed advisor (/advisors/) | V14: Talk to a licensed advisor about permanent cover (/life-insurance/universal-life/) | W14: Book a policy review with a licensed advisor (/advisors/) | X14: Instant life insurance estimate (/quote/) | Y14: Book a policy review with a licensed advisor (/advisors/) | Z14: Request a specialist call: Medical underwriting desk (/life-insurance/medical-conditions/) | AA14: Talk to a licensed advisor about permanent cover (/whole-life-insurance/) | AB14: Instant life insurance estimate (/quote/life-insurance/) | AC14: Request a specialist call: Medical underwriting desk (/life-insurance/medical-conditions/) | AD14: Life insurance needs calculator (/calculators/life-insurance-needs/) | AE14: Talk to a licensed advisor about permanent cover (/whole-life-insurance/) | AF14: Mortgage protection calculator (/calculators/mortgage-protection/) | AG14: Talk to a licensed advisor about permanent cover (/life-insurance/universal-life/) | AH14: Funeral expense estimate, from about $1 a day for the example profile (/life-insurance/funeral-expense/); Request a specialist call: Funeral expense desk | AI14: Life insurance needs calculator (/calculators/life-insurance-needs/) | AJ14: Talk to a licensed advisor about business cover (/business-insurance/key-person/) | AK14: Request a specialist call: Medical underwriting desk (/life-insurance/medical-conditions/) | AL14: Request a specialist call: Medical underwriting desk (/life-insurance/medical-conditions/) | AM14: Instant life insurance estimate (/quote/) | AN14: Instant life insurance estimate (/quote/life-insurance/) | AO14: Life insurance needs calculator (/calculators/life-insurance-needs/) | AP14: Instant critical illness estimate (/critical-illness-insurance/) | AQ14: Talk to a licensed advisor (/life-insurance/children/) | AR14: Life insurance needs calculator (/calculators/life-insurance-needs/) | AS14: Instant health & dental estimate (/health-dental-insurance/) | AT14: Instant health & dental estimate (/health-dental-insurance/) | AU14: Instant life insurance estimate (/quote/) | AV14: Request a specialist call: Medical underwriting desk (/life-insurance/medical-conditions/) | AW14: Book a policy review with a licensed advisor (/advisors/) | AX14: Instant life insurance estimate (/quote/life-insurance/) | AY14: Funeral expense estimate, from about $1 a day for the example profile (/life-insurance/funeral-expense/); Request a specialist call: Funeral expense desk | AZ14: Instant life insurance estimate (/quote/life-insurance/) | BA14: Talk to a licensed advisor about permanent cover (/whole-life-insurance/) | BB14: Mortgage protection calculator (/calculators/mortgage-protection/) | BC14: Request a specialist call: Medical underwriting desk (/life-insurance/medical-conditions/)
